Workbook

Sheet MONTHLY TOTAL
B2: n MONTHLY MINIBAR STATISTICS_Jan 2026
B4: ITEM CODE | C4: ITEM | D4: SALES PRICE | E4: TOTAL AMOUNT | F4: ISSUE TOTAL | J4: TOTAL SOLD | L4: DATE
F5: POSTING | G5: TRANSFER | H5: COMP | I5: SKIPPER | K5: 46022 | L5: 1 | M5: 2 | N5: 3 | O5: 4 | P5: 5 | Q5: 6 | R5: 7 | S5: 8 | T5: 9 | U5: 10 | V5: 11 | W5: 12 | X5: 13 | Y5: 14 | Z5: 15 | AA5: 16 | AB5: 17 | AC5: 18 | AD5: 19 | AE5: 20 | AF5: 21 | AG5: 22 | AH5: 23 | AI5: 24 | AJ5: 25 | AK5: 26 | AL5: 27 | AM5: 28 | AN5: 29 | AO5: 30
B6: 10553408 | C6: Potato Chip | D6: 6000 | E6: =D6*J6 -> 1026000 | F6: ='POSTING,TR,COMP'!F6 -> 130 | G6: ='POSTING,TR,COMP'!F27 -> 0 | H6: ='POSTING,TR,COMP'!F48 -> 0 | I6: =J6-F6 -> 41 | J6: =SUM(K6:AO6) -> 171 | K6: ='Mar 31'!G6 -> 5 | L6: ='1'!G6 -> 6 | M6: ='2'!G6 -> 7 | N6: ='3'!G6 -> 5 | O6: ='4'!G6 -> 7 | P6: ='5'!G6 -> 4 | Q6: ='6'!G6 -> 3 | R6: ='7'!G6 -> 2 | S6: ='8'!G6 -> 6 | T6: ='9'!G6 -> 6 | U6: ='10'!G6 -> 9 | V6: ='11'!G6 -> 4 | W6: ='12'!G6 -> 3 | X6: ='13'!G6 -> 8 | Y6: ='14'!G6 -> 7 | Z6: ='15'!G6 -> 10 | AA6: ='16'!G6 -> 10 | AB6: ='17 (1)'!G6 -> 10 | AC6: ='18'!G6 -> 6 | AD6: ='19'!G6 -> 4 | AE6: ='20'!G6 -> 5 | AF6: ='21'!G6 -> 2 | AG6: ='22'!G6 -> 7 | AH6: ='23'!G6 -> 7 | AI6: ='24'!G6 -> 4 | AJ6: ='25'!G6 -> 10 | AK6: ='26'!G6 -> 9 | AL6: ='27'!G6 -> 2 | AM6: ='28'!G6 -> 3 | AN6: ='29'!G6 -> 0 | AO6: ='30'!G6 -> 0
B7: 10553612 | C7: Haribo Jelly | D7: 6500 | E7: =D7*J7 -> 838500 | F7: ='POSTING,TR,COMP'!F7 -> 95 | G7: ='POSTING,TR,COMP'!F28 -> 0 | H7: ='POSTING,TR,COMP'!F49 -> 0 | I7: =J7-F7 -> 34 | J7: =SUM(K7:AO7) -> 129 | K7: ='Mar 31'!G7 -> 4 | L7: ='1'!G7 -> 3 | M7: ='2'!G7 -> 4 | N7: ='3'!G7 -> 5 | O7: ='4'!G7 -> 7 | P7: ='5'!G7 -> 1 | Q7: ='6'!G7 -> 3 | R7: ='7'!G7 -> 4 | S7: ='8'!G7 -> 3 | T7: ='9'!G7 -> 4 | U7: ='10'!G7 -> 7 | V7: ='11'!G7 -> 2 | W7: ='12'!G7 -> 4 | X7: ='13'!G7 -> 4 | Y7: ='14'!G7 -> 1 | Z7: ='15'!G7 -> 6 | AA7: ='16'!G7 -> 7 | AB7: ='17 (1)'!G7 -> 10 | AC7: ='18'!G7 -> 2 | AD7: ='19'!G7 -> 4 | AE7: ='20'!G7 -> 2 | AF7: ='21'!G7 -> 5 | AG7: ='22'!G7 -> 3 | AH7: ='23'!G7 -> 8 | AI7: ='24'!G7 -> 2 | AJ7: ='25'!G7 -> 6 | AK7: ='26'!G7 -> 9 | AL7: ='27'!G7 -> 3 | AM7: ='28'!G7 -> 6 | AN7: ='29'!G7 -> 0 | AO7: ='30'!G7 -> 0
B8: 10553613 | C8: Fried Squid | D8: 7000 | E8: =D8*J8 -> 406000 | F8: ='POSTING,TR,COMP'!F8 -> 39 | G8: ='POSTING,TR,COMP'!F29 -> 0 | H8: ='POSTING,TR,COMP'!F50 -> 0 | I8: =J8-F8 -> 19 | J8: =SUM(K8:AO8) -> 58 | K8: ='Mar 31'!G8 -> 2 | L8: ='1'!G8 -> 0 | M8: ='2'!G8 -> 7 | N8: ='3'!G8 -> 2 | O8: ='4'!G8 -> 2 | P8: ='5'!G8 -> 1 | Q8: ='6'!G8 -> 1 | R8: ='7'!G8 -> 5 | S8: ='8'!G8 -> 1 | T8: ='9'!G8 -> 2 | U8: ='10'!G8 -> 4 | V8: ='11'!G8 -> 0 | W8: ='12'!G8 -> 3 | X8: ='13'!G8 -> 0 | Y8: ='14'!G8 -> 3 | Z8: ='15'!G8 -> 2 | AA8: ='16'!G8 -> 7 | AB8: ='17 (1)'!G8 -> 2 | AC8: ='18'!G8 -> 1 | AD8: ='19'!G8 -> 1 | AE8: ='20'!G8 -> 1 | AF8: ='21'!G8 -> 1 | AG8: ='22'!G8 -> 4 | AH8: ='23'!G8 -> 3 | AI8: ='24'!G8 -> 2 | AJ8: ='25'!G8 -> 0 | AK8: ='26'!G8 -> 0 | AL8: ='27'!G8 -> 0 | AM8: ='28'!G8 -> 1 | AN8: ='29'!G8 -> 0 | AO8: ='30'!G8 -> 0
B9: 12412003 | C9: Evian | D9: 5500 | E9: =D9*J9 -> 2442000 | F9: ='POSTING,TR,COMP'!F9 -> 331 | G9: ='POSTING,TR,COMP'!F30 -> 0 | H9: ='POSTING,TR,COMP'!F51 -> 17 | I9: =J9-F9 -> 113 | J9: =SUM(K9:AO9) -> 444 | K9: ='Mar 31'!G9 -> 13 | L9: ='1'!G9 -> 14 | M9: ='2'!G9 -> 7 | N9: ='3'!G9 -> 15 | O9: ='4'!G9 -> 18 | P9: ='5'!G9 -> 16 | Q9: ='6'!G9 -> 21 | R9: ='7'!G9 -> 16 | S9: ='8'!G9 -> 20 | T9: ='9'!G9 -> 11 | U9: ='10'!G9 -> 16 | V9: ='11'!G9 -> 18 | W9: ='12'!G9 -> 5 | X9: ='13'!G9 -> 16 | Y9: ='14'!G9 -> 7 | Z9: ='15'!G9 -> 22 | AA9: ='16'!G9 -> 29 | AB9: ='17 (1)'!G9 -> 26 | AC9: ='18'!G9 -> 14 | AD9: ='19'!G9 -> 15 | AE9: ='20'!G9 -> 6 | AF9: ='21'!G9 -> 11 | AG9: ='22'!G9 -> 20 | AH9: ='23'!G9 -> 16 | AI9: ='24'!G9 -> 23 | AJ9: ='25'!G9 -> 22 | AK9: ='26'!G9 -> 7 | AL9: ='27'!G9 -> 9 | AM9: ='28'!G9 -> 11 | AN9: ='29'!G9 -> 0 | AO9: ='30'!G9 -> 0
B10: 12412022 | C10: Coke | D10: 4000 | E10: =D10*J10 -> 204000 | F10: ='POSTING,TR,COMP'!F10 -> 47 | G10: ='POSTING,TR,COMP'!F31 -> 0 | H10: ='POSTING,TR,COMP'!F52 -> 0 | I10: =J10-F10 -> 4 | J10: =SUM(K10:AO10) -> 51 | K10: ='Mar 31'!G10 -> 1 | L10: ='1'!G10 -> 0 | M10: ='2'!G10 -> 1 | N10: ='3'!G10 -> 0 | O10: ='4'!G10 -> 4 | P10: ='5'!G10 -> 1 | Q10: ='6'!G10 -> 3 | R10: ='7'!G10 -> 3 | S10: ='8'!G10 -> 3 | T10: ='9'!G10 -> 1 | U10: ='10'!G10 -> 1 | V10: ='11'!G10 -> 2 | W10: ='12'!G10 -> 1 | X10: ='13'!G10 -> 2 | Y10: ='14'!G10 -> 2 | Z10: ='15'!G10 -> 2 | AA10: ='16'!G10 -> 1 | AB10: ='17 (1)'!G10 -> 5 | AC10: ='18'!G10 -> 3 | AD10: ='19'!G10 -> 3 | AE10: ='20'!G10 -> 2 | AF10: ='21'!G10 -> 1 | AG10: ='22'!G10 -> 1 | AH10: ='23'!G10 -> 2 | AI10: ='24'!G10 -> 2 | AJ10: ='25'!G10 -> 2 | AK10: ='26'!G10 -> 0 | AL10: ='27'!G10 -> 1 | AM10: ='28'!G10 -> 1 | AN10: ='29'!G10 -> 0 | AO10: ='30'!G10 -> 0
B11: 12412023 | C11: Zero Coke | D11: 4000 | E11: =D11*J11 -> 452000 | F11: ='POSTING,TR,COMP'!F11 -> 73 | G11: ='POSTING,TR,COMP'!F32 -> 0 | H11: ='POSTING,TR,COMP'!F53 -> 0 | I11: =J11-F11 -> 40 | J11: =SUM(K11:AO11) -> 113 | K11: ='Mar 31'!G11 -> 0 | L11: ='1'!G11 -> 2 | M11: ='2'!G11 -> 5 | N11: ='3'!G11 -> 10 | O11: ='4'!G11 -> 4 | P11: ='5'!G11 -> 1 | Q11: ='6'!G11 -> 4 | R11: ='7'!G11 -> 1 | S11: ='8'!G11 -> 4 | T11: ='9'!G11 -> 1 | U11: ='10'!G11 -> 3 | V11: ='11'!G11 -> 6 | W11: ='12'!G11 -> 3 | X11: ='13'!G11 -> 1 | Y11: ='14'!G11 -> 5 | Z11: ='15'!G11 -> 9 | AA11: ='16'!G11 -> 3 | AB11: ='17 (1)'!G11 -> 8 | AC11: ='18'!G11 -> 6 | AD11: ='19'!G11 -> 4 | AE11: ='20'!G11 -> 4 | AF11: ='21'!G11 -> 4 | AG11: ='22'!G11 -> 5 | AH11: ='23'!G11 -> 4 | AI11: ='24'!G11 -> 4 | AJ11: ='25'!G11 -> 5 | AK11: ='26'!G11 -> 3 | AL11: ='27'!G11 -> 3 | AM11: ='28'!G11 -> 1 | AN11: ='29'!G11 -> 0 | AO11: ='30'!G11 -> 0
B12: 12412026 | C12: Sprite | D12: 4000 | E12: =D12*J12 -> 220000 | F12: ='POSTING,TR,COMP'!F12 -> 39 | G12: ='POSTING,TR,COMP'!F33 -> 0 | H12: ='POSTING,TR,COMP'!F54 -> 0 | I12: =J12-F12 -> 16 | J12: =SUM(K12:AO12) -> 55 | K12: ='Mar 31'!G12 -> 2 | L12: ='1'!G12 -> 1 | M12: ='2'!G12 -> 1 | N12: ='3'!G12 -> 0 | O12: ='4'!G12 -> 3 | P12: ='5'!G12 -> 2 | Q12: ='6'!G12 -> 2 | R12: ='7'!G12 -> 1 | S12: ='8'!G12 -> 1 | T12: ='9'!G12 -> 2 | U12: ='10'!G12 -> 1 | V12: ='11'!G12 -> 1 | W12: ='12'!G12 -> 1 | X12: ='13'!G12 -> 0 | Y12: ='14'!G12 -> 2 | Z12: ='15'!G12 -> 4 | AA12: ='16'!G12 -> 3 | AB12: ='17 (1)'!G12 -> 2 | AC12: ='18'!G12 -> 3 | AD12: ='19'!G12 -> 1 | AE12: ='20'!G12 -> 2 | AF12: ='21'!G12 -> 2 | AG12: ='22'!G12 -> 1 | AH12: ='23'!G12 -> 5 | AI12: ='24'!G12 -> 4 | AJ12: ='25'!G12 -> 2 | AK12: ='26'!G12 -> 2 | AL12: ='27'!G12 -> 2 | AM12: ='28'!G12 -> 2 | AN12: ='29'!G12 -> 0 | AO12: ='30'!G12 -> 0
B13: 12412239 | C13: Red Bull | D13: 5000 | E13: =D13*J13 -> 180000 | F13: ='POSTING,TR,COMP'!F13 -> 18 | G13: ='POSTING,TR,COMP'!F34 -> 0 | H13: ='POSTING,TR,COMP'!F55 -> 0 | I13: =J13-F13 -> 18 | J13: =SUM(K13:AO13) -> 36 | K13: ='Mar 31'!G13 -> 1 | L13: ='1'!G13 -> 1 | M13: ='2'!G13 -> 0 | N13: ='3'!G13 -> 2 | O13: ='4'!G13 -> 1 | P13: ='5'!G13 -> 2 | Q13: ='6'!G13 -> 0 | R13: ='7'!G13 -> 0 | S13: ='8'!G13 -> 2 | T13: ='9'!G13 -> 0 | U13: ='10'!G13 -> 1 | V13: ='11'!G13 -> 2 | W13: ='12'!G13 -> 0 | X13: ='13'!G13 -> 2 | Y13: ='14'!G13 -> 2 | Z13: ='15'!G13 -> 1 | AA13: ='16'!G13 -> 2 | AB13: ='17 (1)'!G13 -> 4 | AC13: ='18'!G13 -> 0 | AD13: ='19'!G13 -> 0 | AE13: ='20'!G13 -> 0 | AF13: ='21'!G13 -> 0 | AG13: ='22'!G13 -> 1 | AH13: ='23'!G13 -> 2 | AI13: ='24'!G13 -> 3 | AJ13: ='25'!G13 -> 4 | AK13: ='26'!G13 -> 1 | AL13: ='27'!G13 -> 0 | AM13: ='28'!G13 -> 2 | AN13: ='29'!G13 -> 0 | AO13: ='30'!G13 -> 0
B14: 20312001 | C14: Budweiser | D14: 7000 | E14: =D14*J14 -> 378000 | F14: ='POSTING,TR,COMP'!F14 -> 45 | G14: ='POSTING,TR,COMP'!F35 -> 0 | H14: ='POSTING,TR,COMP'!F56 -> 0 | I14: =J14-F14 -> 9 | J14: =SUM(K14:AO14) -> 54 | K14: ='Mar 31'!G14 -> 0 | L14: ='1'!G14 -> 2 | M14: ='2'!G14 -> 3 | N14: ='3'!G14 -> 1 | O14: ='4'!G14 -> 1 | P14: ='5'!G14 -> 1 | Q14: ='6'!G14 -> 1 | R14: ='7'!G14 -> 3 | S14: ='8'!G14 -> 1 | T14: ='9'!G14 -> 1 | U14: ='10'!G14 -> 4 | V14: ='11'!G14 -> 2 | W14: ='12'!G14 -> 0 | X14: ='13'!G14 -> 1 | Y14: ='14'!G14 -> 4 | Z14: ='15'!G14 -> 2 | AA14: ='16'!G14 -> 1 | AB14: ='17 (1)'!G14 -> 5 | AC14: ='18'!G14 -> 1 | AD14: ='19'!G14 -> 3 | AE14: ='20'!G14 -> 1 | AF14: ='21'!G14 -> 3 | AG14: ='22'!G14 -> 1 | AH14: ='23'!G14 -> 3 | AI14: ='24'!G14 -> 2 | AJ14: ='25'!G14 -> 2 | AK14: ='26'!G14 -> 2 | AL14: ='27'!G14 -> 0 | AM14: ='28'!G14 -> 3 | AN14: ='29'!G14 -> 0 | AO14: ='30'!G14 -> 0
B15: 20312002 | C15: Cass | D15: 7000 | E15: =D15*J15 -> 546000 | F15: ='POSTING,TR,COMP'!F15 -> 47 | G15: ='POSTING,TR,COMP'!F36 -> 0 | H15: ='POSTING,TR,COMP'!F57 -> 0 | I15: =J15-F15 -> 31 | J15: =SUM(K15:AO15) -> 78 | K15: ='Mar 31'!G15 -> 2 | L15: ='1'!G15 -> 1 | M15: ='2'!G15 -> 5 | N15: ='3'!G15 -> 2 | O15: ='4'!G15 -> 3 | P15: ='5'!G15 -> 0 | Q15: ='6'!G15 -> 2 | R15: ='7'!G15 -> 4 | S15: ='8'!G15 -> 1 | T15: ='9'!G15 -> 0 | U15: ='10'!G15 -> 6 | V15: ='11'!G15 -> 0 | W15: ='12'!G15 -> 2 | X15: ='13'!G15 -> 1 | Y15: ='14'!G15 -> 6 | Z15: ='15'!G15 -> 7 | AA15: ='16'!G15 -> 2 | AB15: ='17 (1)'!G15 -> 7 | AC15: ='18'!G15 -> 2 | AD15: ='19'!G15 -> 3 | AE15: ='20'!G15 -> 4 | AF15: ='21'!G15 -> 2 | AG15: ='22'!G15 -> 1 | AH15: ='23'!G15 -> 2 | AI15: ='24'!G15 -> 5 | AJ15: ='25'!G15 -> 4 | AK15: ='26'!G15 -> 2 | AL15: ='27'!G15 -> 0 | AM15: ='28'!G15 -> 2 | AN15: ='29'!G15 -> 0 | AO15: ='30'!G15 -> 0
B16: 20312057 | C16: Despina | D16: 7000 | E16: =D16*J16 -> 0 | F16: ='POSTING,TR,COMP'!F16 -> 0 | G16: ='POSTING,TR,COMP'!F37 -> 0 | H16: ='POSTING,TR,COMP'!F58 -> 0 | I16: =J16-F16 -> 0 | J16: =SUM(K16:AO16) -> 0 | K16: ='Mar 31'!G16 -> 0 | L16: ='1'!G16 -> 0 | M16: ='2'!G16 -> 0 | N16: ='3'!G16 -> 0 | O16: ='4'!G16 -> 0 | P16: ='5'!G16 -> 0 | Q16: ='6'!G16 -> 0 | R16: ='7'!G16 -> 0 | S16: ='8'!G16 -> 0 | T16: ='9'!G16 -> 0 | U16: ='10'!G16 -> 0 | V16: ='11'!G16 -> 0 | W16: ='12'!G16 -> 0 | X16: ='13'!G16 -> 0 | Y16: ='14'!G16 -> 0 | Z16: ='15'!G16 -> 0 | AA16: ='16'!G16 -> 0 | AB16: ='17 (1)'!G16 -> 0 | AC16: ='18'!G16 -> 0 | AD16: ='19'!G16 -> 0 | AE16: ='20'!G16 -> 0 | AF16: ='21'!G16 -> 0 | AG16: ='22'!G16 -> 0 | AH16: ='23'!G16 -> 0 | AI16: ='24'!G16 -> 0 | AJ16: ='25'!G16 -> 0 | AK16: ='26'!G16 -> 0 | AL16: ='27'!G16 -> 0 | AM16: ='28'!G16 -> 0 | AN16: ='29'!G16 -> 0 | AO16: ='30'!G16 -> 0
B17: 20312058 | C17: Neptune Pale Ale | D17: 7000 | E17: =D17*J17 -> 0 | F17: ='POSTING,TR,COMP'!F17 -> 0 | G17: ='POSTING,TR,COMP'!F38 -> 0 | H17: ='POSTING,TR,COMP'!F59 -> 0 | I17: =J17-F17 -> 0 | J17: =SUM(K17:AO17) -> 0 | K17: ='Mar 31'!G17 -> 0 | L17: ='1'!G17 -> 0 | M17: ='2'!G17 -> 0 | N17: ='3'!G17 -> 0 | O17: ='4'!G17 -> 0 | P17: ='5'!G17 -> 0 | Q17: ='6'!G17 -> 0 | R17: ='7'!G17 -> 0 | S17: ='8'!G17 -> 0 | T17: ='9'!G17 -> 0 | U17: ='10'!G17 -> 0 | V17: ='11'!G17 -> 0 | W17: ='12'!G17 -> 0 | X17: ='13'!G17 -> 0 | Y17: ='14'!G17 -> 0 | Z17: ='15'!G17 -> 0 | AA17: ='16'!G17 -> 0 | AB17: ='17 (1)'!G17 -> 0 | AC17: ='18'!G17 -> 0 | AD17: ='19'!G17 -> 0 | AE17: ='20'!G17 -> 0 | AF17: ='21'!G17 -> 0 | AG17: ='22'!G17 -> 0 | AH17: ='23'!G17 -> 0 | AI17: ='24'!G17 -> 0 | AJ17: ='25'!G17 -> 0 | AK17: ='26'!G17 -> 0 | AL17: ='27'!G17 -> 0 | AM17: ='28'!G17 -> 0 | AN17: ='29'!G17 -> 0 | AO17: ='30'!G17 -> 0
... B19: 20312060 | C19: No.5 Stout | D19: 7000 | E19: =D19*J19 -> 0 | F19: ='POSTING,TR,COMP'!F19 -> 0 | G19: ='POSTING,TR,COMP'!F40 -> 0 | H19: ='POSTING,TR,COMP'!F61 -> 0 | I19: =J19-F19 -> 0 | J19: =SUM(K19:AO19) -> 0 | K19: ='Mar 31'!G19 -> 0 | L19: ='1'!G19 -> 0 | M19: ='2'!G19 -> 0 | N19: ='3'!G19 -> 0 | O19: ='4'!G19 -> 0 | P19: ='5'!G19 -> 0 | Q19: ='6'!G19 -> 0 | R19: ='7'!G19 -> 0 | S19: ='8'!G19 -> 0 | T19: ='9'!G19 -> 0 | U19: ='10'!G19 -> 0 | V19: ='11'!G19 -> 0 | W19: ='12'!G19 -> 0 | X19: ='13'!G19 -> 0 | Y19: ='14'!G19 -> 0 | Z19: ='15'!G19 -> 0 | AA19: ='16'!G19 -> 0 | AB19: ='17 (1)'!G19 -> 0 | AC19: ='18'!G19 -> 0 | AD19: ='19'!G19 -> 0 | AE19: ='20'!G19 -> 0 | AF19: ='21'!G19 -> 0 | AG19: ='22'!G19 -> 0 | AH19: ='23'!G19 -> 0 | AI19: ='24'!G19 -> 0 | AJ19: ='25'!G19 -> 0 | AK19: ='26'!G19 -> 0 | AL19: ='27'!G19 -> 0 | AM19: ='28'!G19 -> 0 | AN19: ='29'!G19 -> 0 | AO19: ='30'!G19 -> 0
B20: TOTAL | D20: =SUM(D6:D8,D10:D15)+D9*2 -> 61500 | E20: =SUM(E6:E19) -> 6692500 | F20: =SUM(F6:F19) -> 864 | G20: =SUM(G6:G19) -> 0 | H20: =SUM(H6:H19) -> 17 | I20: =SUM(I6:I19) -> 325 | J20: =SUM(J6:J19) -> 1189 | K20: =SUM(K6:K19) -> 30 | L20: =SUM(L6:L19) -> 30 | ... AO20: =SUM(AO6:AO19) -> 0
F21: =$D6*F6+$D7*F7+$D8*F8+$D9*F9+$D10*F10+$D11*F11+$D12*F12+$D13*F13+$D14*F14+$D15*F15+$D16*F16+$D17*F17+$D18*F18+$D19*F19 -> 4861000 | G21: =$D6*G6+$D7*G7+$D8*G8+$D9*G9+$D10*G10+$D11*G11+$D12*G12+$D13*G13+$D14*G14+$D15*G15+$D16*G16+$D17*G17+$D18*G18+$D19*G19 -> 0 | H21: =$D6*H6+$D7*H7+$D8*H8+$D9*H9+$D10*H10+$D11*H11+$D12*H12+$D13*H13+$D14*H14+$D15*H15+$D16*H16+$D17*H17+$D18*H18+$D19*H19 -> 93500 | I21: =$D6*I6+$D7*I7+$D8*I8+$D9*I9+$D10*I10+$D11*I11+$D12*I12+$D13*I13+$D14*I14+$D15*I15+$D16*I16+$D17*I17+$D18*I18+$D19*I19 -> 1831500 | J21: =$D6*J6+$D7*J7+$D8*J8+$D9*J9+$D10*J10+$D11*J11+$D12*J12+$D13*J13+$D14*J14+$D15*J15+$D16*J16+$D17*J17+$D18*J18+$D19*J19 -> 6692500 | K21: =$D6*K6+$D7*K7+$D8*K8+$D9*K9+$D10*K10+$D11*K11+$D12*K12+$D13*K13+$D14*K14+$D15*K15+$D16*K16+$D17*K17+$D18*K18+$D19*K19 -> 172500 | L21: =$D6*L6+$D7*L7+$D8*L8+$D9*L9+$D10*L10+$D11*L11+$D12*L12+$D13*L13+$D14*L14+$D15*L15+$D16*L16+$D17*L17+$D18*L18+$D19*L19 -> 170500 | M21: =$D6*M6+$D7*M7+$D8*M8+$D9*M9+$D10*M10+$D11*M11+$D12*M12+$D13*M13+$D14*M14+$D15*M15+$D16*M16+$D17*M17+$D18*M18+$D19*M19 -> 239500 | ... AO21: =$D6*AO6+$D7*AO7+$D8*AO8+$D9*AO9+$D10*AO10+$D11*AO11+$D12*AO12+$D13*AO13+$D14*AO14+$D15*AO15+$D16*AO16+$D17*AO17+$D18*AO18+$D19*AO19 -> 0
F22: TTL Posting Ratio % | I22: =F21/J21 -> 0.72633545 | J22: Posting | K22: ='POSTING,TR,COMP'!G21 -> 130500 | L22: ='POSTING,TR,COMP'!H21 -> 241000 | M22: ='POSTING,TR,COMP'!I21 -> 197500 | N22: ='POSTING,TR,COMP'!J21 -> 159000 | O22: ='POSTING,TR,COMP'!K21 -> 218500 | P22: ='POSTING,TR,COMP'!L21 -> 148000 | Q22: ='POSTING,TR,COMP'!M21 -> 127500 | R22: ='POSTING,TR,COMP'!N21 -> 192500 | ... AO22: ='POSTING,TR,COMP'!AK21 -> 0
J23: Ratio % | K23: =K22/K21 -> 0.75652174 | L23: =L22/L21 -> 1.4134897 | M23: =M22/M21 -> 0.82463466 | N23: =N22/N21 -> 0.69130435 | O23: =O22/O21 -> 0.78738739 | P23: =P22/P21 -> 0.93375394 | Q23: =Q22/Q21 -> 0.5875576 | R23: =R22/R21 -> 0.83695652 | ... AO23: =AO22/AO21 -> #DIV/0!

Sheet POSTING,TR,COMP
B2: n MONTHLY POSTING
B4: ITEM CODE | C4: ITEM | D4: SALES PRICE | E4: TOTAL AMOUNT | F4: TOTAL POSTING | H4: DATE
G5: 31 | H5: 1 | I5: 2 | J5: 3 | K5: 4 | L5: 5 | M5: 6 | N5: 7 | O5: 8 | P5: 9 | Q5: 10 | R5: 11 | S5: 12 | T5: 13 | U5: 14 | V5: 15 | W5: 16 | X5: 17 | Y5: 18 | Z5: 19 | AA5: 20 | AB5: 21 | AC5: 22 | AD5: 23 | AE5: 24 | AF5: 25 | AG5: 26 | AH5: 27 | AI5: 28 | AJ5: 29 | AK5: 30 | AL5: 31
B6: 10553408 | C6: Potato Chip | D6: 6000 | E6: =D6*F6 -> 780000 | F6: =SUM(G6:AL6) -> 130 | G6: 3 | H6: 5 | I6: 5 | J6: 7 | K6: 5 | L6: 4 | M6: 3 | N6: 2 | O6: 5 | P6: 3 | Q6: 3 | R6: 4 | T6: 4 | U6: 5 | V6: 8 | W6: 9 | X6: 7 | Y6: 6 | Z6: 2 | AA6: 5 | AB6: 4 | AC6: 4 | AD6: 8 | AE6: 3 | AF6: 7 | AG6: 8 | AH6: 1
B7: 10553612 | C7: Haribo Jelly | D7: 6500 | E7: =D7*F7 -> 617500 | F7: =SUM(G7:AL7) -> 95 | G7: 3 | H7: 7 | I7: 2 | J7: 3 | K7: 5 | L7: 1 | N7: 4 | O7: 2 | P7: 5 | Q7: 3 | R7: 1 | S7: 3 | T7: 4 | U7: 2 | V7: 6 | W7: 6 | X7: 4 | Y7: 2 | Z7: 1 | AA7: 2 | AB7: 4 | AC7: 3 | AD7: 8 | AE7: 2 | AF7: 3 | AG7: 8 | AH7: 1
B8: 10553613 | C8: Fried Squid | D8: 7000 | E8: =D8*F8 -> 273000 | F8: =SUM(G8:AL8) -> 39 | G8: 1 | H8: 2 | I8: 4 | J8: 2 | K8: 2 | L8: 1 | N8: 4 | P8: 1 | Q8: 1 | R8: 1 | S8: 2 | U8: 2 | V8: 1 | W8: 6 | X8: 1 | AB8: 1 | AC8: 3 | AD8: 2 | AE8: 2
B9: 12412003 | C9: Evian | D9: 5500 | E9: =D9*F9 -> 1820500 | F9: =SUM(G9:AL9) -> 331 | G9: 12 | H9: 15 | I9: 9 | J9: 9 | K9: 18 | L9: 13 | M9: 15 | N9: 13 | O9: 13 | P9: 10 | Q9: 6 | R9: 13 | S9: 2 | T9: 15 | U9: 8 | V9: 20 | W9: 22 | X9: 8 | Y9: 13 | Z9: 7 | AA9: 6 | AB9: 11 | AC9: 12 | AD9: 17 | AE9: 13 | AF9: 19 | AG9: 6 | AH9: 6
B10: 12412022 | C10: Coke | D10: 4000 | E10: =D10*F10 -> 188000 | F10: =SUM(G10:AL10) -> 47 | H10: 2 | I10: 1 | K10: 1 | M10: 1 | N10: 4 | O10: 1 | P10: 2 | Q10: 1 | R10: 2 | S10: 1 | T10: 1 | U10: 2 | V10: 2 | W10: 2 | X10: 6 | Y10: 3 | Z10: 3 | AA10: 1 | AB10: 2 | AD10: 2 | AE10: 2 | AF10: 2 | AG10: 3
B11: 12412023 | C11: Zero Coke | D11: 4000 | E11: =D11*F11 -> 292000 | F11: =SUM(G11:AL11) -> 73 | H11: 2 | I11: 4 | J11: 2 | K11: 4 | L11: 8 | M11: 3 | O11: 3 | P11: 1 | Q11: 1 | R11: 4 | S11: 1 | T11: 1 | U11: 3 | V11: 8 | W11: 1 | X11: 2 | Y11: 2 | Z11: 2 | AA11: 3 | AB11: 4 | AC11: 1 | AD11: 3 | AE11: 2 | AF11: 4 | AG11: 2 | AH11: 2
B12: 12412026 | C12: Sprite | D12: 4000 | E12: =D12*F12 -> 156000 | F12: =SUM(G12:AL12) -> 39 | G12: 2 | H12: 2 | I12: 2 | K12: 1 | M12: 1 | N12: 1 | O12: 1 | P12: 1 | R12: 3 | U12: 3 | V12: 3 | W12: 3 | X12: 2 | Z12: 1 | AB12: 1 | AD12: 4 | AE12: 4 | AF12: 2 | AG12: 1 | AH12: 1
B13: 12412239 | C13: Red Bull | D13: 5000 | E13: =D13*F13 -> 90000 | F13: =SUM(G13:AL13) -> 18 | G13: 1 | H13: 2 | J13: 1 | K13: 1 | O13: 1 | R13: 2 | T13: 1 | U13: 1 | W13: 2 | X13: 1 | AA13: 1 | AE13: 2 | AF13: 2
B14: 20312001 | C14: Budweiser | D14: 7000 | E14: =D14*F14 -> 315000 | F14: =SUM(G14:AL14) -> 45 | G14: 1 | H14: 3 | I14: 3 | J14: 2 | K14: 1 | L14: 1 | N14: 2 | O14: 1 | Q14: 2 | R14: 4 | T14: 1 | U14: 4 | V14: 4 | W14: 1 | X14: 1 | Y14: 1 | Z14: 2 | AA14: 3 | AB14: 1 | AC14: 1 | AD14: 1 | AE14: 2 | AF14: 1 | AG14: 2
B15: 20312002 | C15: Cass | D15: 7000 | E15: =D15*F15 -> 329000 | F15: =SUM(G15:AL15) -> 47 | H15: 2 | I15: 4 | J15: 1 | K15: 1 | M15: 1 | N15: 3 | O15: 1 | P15: 1 | Q15: 2 | R15: 3 | T15: 1 | U15: 4 | V15: 3 | W15: 1 | X15: 2 | Y15: 1 | Z15: 2 | AA15: 4 | AB15: 1 | AC15: 1 | AD15: 2 | AE15: 3 | AF15: 1 | AG15: 2
B16: 20312057 | C16: Despina | D16: 7000 | E16: =D16*F16 -> 0 | F16: =SUM(G16:AL16) -> 0
B17: 20312058 | C17: Neptune Pale Ale | D17: 7000 | E17: =D17*F17 -> 0 | F17: =SUM(G17:AL17) -> 0
B18: 20312059 | C18: Two Face Black IPA | D18: 7000 | E18: =D18*F18 -> 0 | F18: =SUM(G18:AL18) -> 0
B19: 20312060 | C19: No.5 Stout | D19: 7000 | E19: =D19*F19 -> 0 | F19: =SUM(G19:AL19) -> 0
B20: TOTAL | D20: =SUM(D6:D8,D10:D15)+D9*2 -> 61500 | E20: =SUM(E6:E19) -> 4861000 | F20: =SUM(F6:F19) -> 864 | G20: =SUM(G6:G19) -> 23 | H20: =SUM(H6:H19) -> 42 | I20: =SUM(I6:I19) -> 34 | J20: =SUM(J6:J19) -> 27 | K20: =SUM(K6:K19) -> 39 | L20: =SUM(L6:L19) -> 28 | ... AL20: =SUM(AL6:AL19) -> 0
F21: =$D6*F6+$D7*F7+$D8*F8+$D9*F9+$D10*F10+$D11*F11+$D12*F12+$D13*F13+$D14*F14+$D15*F15+$D16*F16+$D17*F17+$D18*F18+$D19*F19 -> 4861000 | G21: =$D6*G6+$D7*G7+$D8*G8+$D9*G9+$D10*G10+$D11*G11+$D12*G12+$D13*G13+$D14*G14+$D15*G15+$D16*G16+$D17*G17+$D18*G18+$D19*G19 -> 130500 | H21: =$D6*H6+$D7*H7+$D8*H8+$D9*H9+$D10*H10+$D11*H11+$D12*H12+$D13*H13+$D14*H14+$D15*H15+$D16*H16+$D17*H17+$D18*H18+$D19*H19 -> 241000 | I21: =$D6*I6+$D7*I7+$D8*I8+$D9*I9+$D10*I10+$D11*I11+$D12*I12+$D13*I13+$D14*I14+$D15*I15+$D16*I16+$D17*I17+$D18*I18+$D19*I19 -> 197500 | J21: =$D6*J6+$D7*J7+$D8*J8+$D9*J9+$D10*J10+$D11*J11+$D12*J12+$D13*J13+$D14*J14+$D15*J15+$D16*J16+$D17*J17+$D18*J18+$D19*J19 -> 159000 | K21: =$D6*K6+$D7*K7+$D8*K8+$D9*K9+$D10*K10+$D11*K11+$D12*K12+$D13*K13+$D14*K14+$D15*K15+$D16*K16+$D17*K17+$D18*K18+$D19*K19 -> 218500 | L21: =$D6*L6+$D7*L7+$D8*L8+$D9*L9+$D10*L10+$D11*L11+$D12*L12+$D13*L13+$D14*L14+$D15*L15+$D16*L16+$D17*L17+$D18*L18+$D19*L19 -> 148000 | M21: =$D6*M6+$D7*M7+$D8*M8+$D9*M9+$D10*M10+$D11*M11+$D12*M12+$D13*M13+$D14*M14+$D15*M15+$D16*M16+$D17*M17+$D18*M18+$D19*M19 -> 127500 | ... AL21: =$D6*AL6+$D7*AL7+$D8*AL8+$D9*AL9+$D10*AL10+$D11*AL11+$D12*AL12+$D13*AL13+$D14*AL14+$D15*AL15+$D16*AL16+$D17*AL17+$D18*AL18+$D19*AL19 -> 0
B23: n MONTHLY TRANSFER_Damage, Expiration date
B25: ITEM CODE | C25: ITEM | D25: SALES PRICE | E25: TOTAL AMOUNT | F25: TOTAL POSTING | H25: DATE
G26: =G5 -> 31 | H26: 1 | I26: 2 | J26: 3 | K26: 4 | L26: 5 | M26: 6 | N26: 7 | O26: 8 | P26: 9 | Q26: 10 | R26: 11 | S26: 12 | T26: 13 | U26: 14 | V26: 15 | W26: 16 | X26: 17 | Y26: 18 | Z26: 19 | AA26: 20 | AB26: 21 | AC26: 22 | AD26: 23 | AE26: 24 | AF26: 25 | AG26: 26 | AH26: 27 | AI26: 28 | AJ26: 29 | AK26: 30 | AL26: 31
B27: 10553408 | C27: Potato Chip | D27: 6000 | E27: =D27*F27 -> 0 | F27: =SUM(G27:AL27) -> 0
B28: 10553612 | C28: Haribo Jelly | D28: 6500 | E28: =D28*F28 -> 0 | F28: =SUM(G28:AL28) -> 0
B29: 10553613 | C29: Fried Squid | D29: 7000 | E29: =D29*F29 -> 0 | F29: =SUM(G29:AL29) -> 0
B30: 12412003 | C30: Evian | D30: 5500 | E30: =D30*F30 -> 0 | F30: =SUM(G30:AL30) -> 0
B31: 12412022 | C31: Coke | D31: 4000 | E31: =D31*F31 -> 0 | F31: =SUM(G31:AL31) -> 0
B32: 12412023 | C32: Zero Coke | D32: 4000 | E32: =D32*F32 -> 0 | F32: =SUM(G32:AL32) -> 0
B33: 12412026 | C33: Sprite | D33: 4000 | E33: =D33*F33 -> 0 | F33: =SUM(G33:AL33) -> 0
B34: 12412239 | C34: Red Bull | D34: 5000 | E34: =D34*F34 -> 0 | F34: =SUM(G34:AL34) -> 0
B35: 20312001 | C35: Budweiser | D35: 7000 | E35: =D35*F35 -> 0 | F35: =SUM(G35:AL35) -> 0
B36: 20312002 | C36: Cass | D36: 7000 | E36: =D36*F36 -> 0 | F36: =SUM(G36:AL36) -> 0
B37: 20312057 | C37: Despina | D37: 7000 | E37: =D37*F37 -> 0 | F37: =SUM(G37:AL37) -> 0
B38: 20312058 | C38: Neptune Pale Ale | D38: 7000 | E38: =D38*F38 -> 0 | F38: =SUM(G38:AL38) -> 0
... B40: 20312060 | C40: No.5 Stout | D40: 7000 | E40: =D40*F40 -> 0 | F40: =SUM(G40:AL40) -> 0
B41: TOTAL | D41: =SUM(D27:D29,D31:D36)+D30*2 -> 61500 | E41: =SUM(E27:E40) -> 0 | F41: =SUM(F27:F40) -> 0 | G41: =SUM(G27:G40) -> 0 | H41: =SUM(H27:H40) -> 0 | I41: =SUM(I27:I40) -> 0 | J41: =SUM(J27:J40) -> 0 | K41: =SUM(K27:K40) -> 0 | L41: =SUM(L27:L40) -> 0 | ... AL41: =SUM(AL27:AL40) -> 0
F42: =$D27*F27+$D28*F28+$D29*F29+$D30*F30+$D31*F31+$D32*F32+$D33*F33+$D34*F34+$D35*F35+$D36*F36+$D37*F37+$D38*F38+$D39*F39+$D40*F40 -> 0 | G42: =$D27*G27+$D28*G28+$D29*G29+$D30*G30+$D31*G31+$D32*G32+$D33*G33+$D34*G34+$D35*G35+$D36*G36+$D37*G37+$D38*G38+$D39*G39+$D40*G40 -> 0 | H42: =$D27*H27+$D28*H28+$D29*H29+$D30*H30+$D31*H31+$D32*H32+$D33*H33+$D34*H34+$D35*H35+$D36*H36+$D37*H37+$D38*H38+$D39*H39+$D40*H40 -> 0 | I42: =$D27*I27+$D28*I28+$D29*I29+$D30*I30+$D31*I31+$D32*I32+$D33*I33+$D34*I34+$D35*I35+$D36*I36+$D37*I37+$D38*I38+$D39*I39+$D40*I40 -> 0 | J42: =$D27*J27+$D28*J28+$D29*J29+$D30*J30+$D31*J31+$D32*J32+$D33*J33+$D34*J34+$D35*J35+$D36*J36+$D37*J37+$D38*J38+$D39*J39+$D40*J40 -> 0 | K42: =$D27*K27+$D28*K28+$D29*K29+$D30*K30+$D31*K31+$D32*K32+$D33*K33+$D34*K34+$D35*K35+$D36*K36+$D37*K37+$D38*K38+$D39*K39+$D40*K40 -> 0 | L42: =$D27*L27+$D28*L28+$D29*L29+$D30*L30+$D31*L31+$D32*L32+$D33*L33+$D34*L34+$D35*L35+$D36*L36+$D37*L37+$D38*L38+$D39*L39+$D40*L40 -> 0 | M42: =$D27*M27+$D28*M28+$D29*M29+$D30*M30+$D31*M31+$D32*M32+$D33*M33+$D34*M34+$D35*M35+$D36*M36+$D37*M37+$D38*M38+$D39*M39+$D40*M40 -> 0 | ... AL42: =$D27*AL27+$D28*AL28+$D29*AL29+$D30*AL30+$D31*AL31+$D32*AL32+$D33*AL33+$D34*AL34+$D35*AL35+$D36*AL36+$D37*AL37+$D38*AL38+$D39*AL39+$D40*AL40 -> 0
B44: n MONTHLY COMP
B46: ITEM CODE | C46: ITEM | D46: SALES PRICE | E46: TOTAL AMOUNT | F46: TOTAL POSTING | H46: DATE
G47: =G5 -> 31 | H47: 1 | I47: 2 | J47: 3 | K47: 4 | L47: 5 | M47: 6 | N47: 7 | O47: 8 | P47: 9 | Q47: 10 | R47: 11 | S47: 12 | T47: 13 | U47: 14 | V47: 15 | W47: 16 | X47: 17 | Y47: 18 | Z47: 19 | AA47: 20 | AB47: 21 | AC47: 22 | AD47: 23 | AE47: 24 | AF47: 25 | AG47: 26 | AH47: 27 | AI47: 28 | AJ47: 29 | AK47: 30 | AL47: 31
...

Sheet Mar 31
B2: ■ DAILY MINIBAR SALES
B4: ITEM | C4: EXPIRATION DATE 1 | D4: EXPIRATION DATE 2 | E4: SALES PRICE | F4: TOTAL AMOUNT | G4: No. | H4: 1 | I4: 2 | J4: 3 | K4: 4 | L4: 5 | M4: 6 | N4: 7 | O4: 8 | P4: 9 | Q4: 10 | R4: 11 | S4: 12 | T4: 13 | U4: 14 | V4: 15 | W4: 16 | X4: 17 | Y4: 18 | Z4: 19 | AA4: 20 | AB4: 21 | AC4: 22 | AD4: 23 | AE4: 24 | AF4: 25 | AG4: 26 | AH4: 27 | AI4: 28 | AJ4: 29 | AK4: 30 | AL4: 31 | AM4: 32 | AN4: 33 | AO4: 34 | AP4: 35 | AQ4: 36 | AR4: 37 | AS4: 38 | AT4: 39 | AU4: 40
G5: Room No. | H5: 1128 | I5: 1120 | J5: 914 | K5: 1717 | L5: 1429 | M5: 1220 | N5: 1215 | O5: 1101 | P5: 925 | Q5: 1415 | R5: 1419 | S5: 1024 | T5: 1029 | U5: 825 | V5: 510 | W5: 1225 | X5: 1631 | Y5: 1125 | Z5: 1625
B6: Potato Chip 감자칩 | C6: 2026년11월 | E6: 6000 | F6: =E6*G6 -> 30000 | G6: =SUM(H6:AU6) -> 5 | K6: 1 | N6: 1 | Q6: 1 | T6: 1 | Y6: 1
B7: Haribo Jelly 하리보 | C7: 2026년11월 | E7: 6500 | F7: =E7*G7 -> 26000 | G7: =SUM(H7:AU7) -> 4 | I7: 1 | K7: 1 | M7: 1 | S7: 1
B8: Fried Squid 오징어 | C8: 2026년10월 | D8: 2026년11월 | E8: 7000 | F8: =E8*G8 -> 14000 | G8: =SUM(H8:AU8) -> 2 | K8: 1 | M8: 1
B9: Evian 에비앙 | C9: 2027년08월 | E9: 5500 | F9: =E9*G9 -> 71500 | G9: =SUM(H9:AU9) -> 13 | H9: 1 | J9: 1 | L9: 2 | O9: 1 | R9: 2 | S9: 1 | U9: 1 | V9: 1 | W9: 2 | X9: 1
B10: Coke 콜라 | C10: 2027년12월 | E10: 4000 | F10: =E10*G10 -> 4000 | G10: =SUM(H10:AU10) -> 1 | K10: 1
B11: Zero Coke 제로 콜라 | C11: 2027년2월 | E11: 4000 | F11: =E11*G11 -> 0 | G11: =SUM(H11:AU11) -> 0
B12: Sprite 스프라이트 | C12: 2028년1월 | E12: 4000 | F12: =E12*G12 -> 8000 | G12: =SUM(H12:AU12) -> 2 | P12: 1 | Q12: 1
B13: Red Bull 레드불 | C13: 2027년2월 | E13: 5000 | F13: =E13*G13 -> 5000 | G13: =SUM(H13:AU13) -> 1 | Z13: 1
B14: Budweiser 버드와이저 | C14: 2026년11월 | E14: 7000 | F14: =E14*G14 -> 0 | G14: =SUM(H14:AU14) -> 0
B15: Cass 카스 | C15: 2027년1월 | E15: 7000 | F15: =E15*G15 -> 14000 | G15: =SUM(H15:AU15) -> 2 | K15: 1 | Y15: 1
B16: Despina 데스피나 | E16: 7000 | F16: =E16*G16 -> 0 | G16: =SUM(H16:AU16) -> 0
B17: Neptune Pale Ale 넵튠 에일 | E17: 7000 | F17: =E17*G17 -> 0 | G17: =SUM(H17:AU17) -> 0
B18: Two Face Black IPA 투페이스 | E18: 7000 | F18: =E18*G18 -> 0 | G18: =SUM(H18:AU18) -> 0
B19: No.5 Stout 넘버5 | E19: 7000 | F19: =E19*G19 -> 0 | G19: =SUM(H19:AU19) -> 0
B20: TOTAL | E20: =SUM(E6:E8,E10:E15)+E9*2 -> 61500 | F20: =SUM(F6:F19) -> 172500 | G20: =SUM(G6:G19) -> 30 | H20: =SUM(H6:H19) -> 1 | I20: =SUM(I6:I19) -> 1 | J20: =SUM(J6:J19) -> 1 | K20: =SUM(K6:K19) -> 5 | L20: =SUM(L6:L19) -> 2 | M20: =SUM(M6:M19) -> 2 | ... AU20: =SUM(AU6:AU19) -> 0
H21: =$E6*H6+$E7*H7+$E8*H8+$E9*H9+$E10*H10+$E11*H11+$E12*H12+$E14*H14+$E15*H15+$E16*H16+$E17*H17+$E18*H18+$E19*H19+$E13*H13 -> 5500 | I21: =$E6*I6+$E7*I7+$E8*I8+$E9*I9+$E10*I10+$E11*I11+$E12*I12+$E14*I14+$E15*I15+$E16*I16+$E17*I17+$E18*I18+$E19*I19+$E13*I13 -> 6500 | J21: =$E6*J6+$E7*J7+$E8*J8+$E9*J9+$E10*J10+$E11*J11+$E12*J12+$E14*J14+$E15*J15+$E16*J16+$E17*J17+$E18*J18+$E19*J19+$E13*J13 -> 5500 | K21: =$E6*K6+$E7*K7+$E8*K8+$E9*K9+$E10*K10+$E11*K11+$E12*K12+$E14*K14+$E15*K15+$E16*K16+$E17*K17+$E18*K18+$E19*K19+$E13*K13 -> 30500 | L21: =$E6*L6+$E7*L7+$E8*L8+$E9*L9+$E10*L10+$E11*L11+$E12*L12+$E14*L14+$E15*L15+$E16*L16+$E17*L17+$E18*L18+$E19*L19+$E13*L13 -> 11000 | M21: =$E6*M6+$E7*M7+$E8*M8+$E9*M9+$E10*M10+$E11*M11+$E12*M12+$E14*M14+$E15*M15+$E16*M16+$E17*M17+$E18*M18+$E19*M19+$E13*M13 -> 13500 | N21: =$E6*N6+$E7*N7+$E8*N8+$E9*N9+$E10*N10+$E11*N11+$E12*N12+$E14*N14+$E15*N15+$E16*N16+$E17*N17+$E18*N18+$E19*N19+$E13*N13 -> 6000 | O21: =$E6*O6+$E7*O7+$E8*O8+$E9*O9+$E10*O10+$E11*O11+$E12*O12+$E14*O14+$E15*O15+$E16*O16+$E17*O17+$E18*O18+$E19*O19+$E13*O13 -> 5500 | ... AU21: =$E6*AU6+$E7*AU7+$E8*AU8+$E9*AU9+$E10*AU10+$E11*AU11+$E12*AU12+$E14*AU14+$E15*AU15+$E16*AU16+$E17*AU17+$E18*AU18+$E19*AU19+$E13*AU13 -> 0

Sheet 1
B2: ■ DAILY MINIBAR SALES
B4: ITEM | C4: EXPIRATION DATE 1 | D4: EXPIRATION DATE 2 | E4: SALES PRICE | F4: TOTAL AMOUNT | G4: No. | H4: 1 | I4: 2 | J4: 3 | K4: 4 | L4: 5 | M4: 6 | N4: 7 | O4: 8 | P4: 9 | Q4: 10 | R4: 11 | S4: 12 | T4: 13 | U4: 14 | V4: 15 | W4: 16 | X4: 17 | Y4: 18 | Z4: 19 | AA4: 20 | AB4: 21 | AC4: 22 | AD4: 23 | AE4: 24 | AF4: 25 | AG4: 26 | AH4: 27 | AI4: 28 | AJ4: 29 | AK4: 30 | AL4: 31 | AM4: 32 | AN4: 33 | AO4: 34 | AP4: 35 | AQ4: 36 | AR4: 37 | AS4: 38 | AT4: 39 | AU4: 40
G5: Room No. | H5: 1002 | I5: 1426 | J5: 1701 | K5: 1627 | L5: 1001 | M5: 709 | N5: 1114 | O5: 711 | P5: 1601 | Q5: 901 | R5: 1101 | S5: 1225 | T5: 1625 | U5: 1014 | V5: 510 | W5: 1528 | X5: 501 | Y5: 1128 | Z5: 914 | AA5: 1415 | AB5: 1503 | AC5: 1021
B6: Potato Chip 감자칩 | C6: 2026년11월 | E6: 6000 | F6: =E6*G6 -> 36000 | G6: =SUM(H6:AU6) -> 6 | I6: 1 | K6: 1 | R6: 1 | T6: 1 | AA6: 1 | AB6: 1
B7: Haribo Jelly 하리보 | C7: 2026년11월 | E7: 6500 | F7: =E7*G7 -> 19500 | G7: =SUM(H7:AU7) -> 3 | J7: 1 | O7: 1 | P7: 1
B8: Fried Squid 오징어 | C8: 2026년10월 | D8: 2026년9월 | E8: 7000 | F8: =E8*G8 -> 0 | G8: =SUM(H8:AU8) -> 0
B9: Evian 에비앙 | C9: 2027년08월 | E9: 5500 | F9: =E9*G9 -> 77000 | G9: =SUM(H9:AU9) -> 14 | H9: 2 | L9: 2 | N9: 1 | Q9: 1 | S9: 2 | U9: 1 | V9: 1 | W9: 1 | Y9: 1 | Z9: 2
B10: Coke 콜라 | C10: 2027년12월 | E10: 4000 | F10: =E10*G10 -> 0 | G10: =SUM(H10:AU10) -> 0
B11: Zero Coke 제로 콜라 | C11: 2027년2월 | E11: 4000 | F11: =E11*G11 -> 8000 | G11: =SUM(H11:AU11) -> 2 | U11: 1 | X11: 1
B12: Sprite 스프라이트 | C12: 2028년1월 | E12: 4000 | F12: =E12*G12 -> 4000 | G12: =SUM(H12:AU12) -> 1 | AC12: 1
B13: Red Bull 레드불 | C13: 2027년2월 | E13: 5000 | F13: =E13*G13 -> 5000 | G13: =SUM(H13:AU13) -> 1 | T13: 1
B14: Budweiser 버드와이저 | C14: 2026년11월 | E14: 7000 | F14: =E14*G14 -> 14000 | G14: =SUM(H14:AU14) -> 2 | M14: 1 | X14: 1
B15: Cass 카스 | C15: 2027년1월 | E15: 7000 | F15: =E15*G15 -> 7000 | G15: =SUM(H15:AU15) -> 1 | M15: 1
B16: Despina 데스피나 | E16: 7000 | F16: =E16*G16 -> 0 | G16: =SUM(H16:AU16) -> 0
B17: Neptune Pale Ale 넵튠 에일 | E17: 7000 | F17: =E17*G17 -> 0 | G17: =SUM(H17:AU17) -> 0
B18: Two Face Black IPA 투페이스 | E18: 7000 | F18: =E18*G18 -> 0 | G18: =SUM(H18:AU18) -> 0
B19: No.5 Stout 넘버5 | E19: 7000 | F19: =E19*G19 -> 0 | G19: =SUM(H19:AU19) -> 0
B20: TOTAL | E20: =SUM(E6:E8,E10:E15)+E9*2 -> 61500 | F20: =SUM(F6:F19) -> 170500 | G20: =SUM(G6:G19) -> 30 | H20: =SUM(H6:H19) -> 2 | I20: =SUM(I6:I19) -> 1 | J20: =SUM(J6:J19) -> 1 | K20: =SUM(K6:K19) -> 1 | L20: =SUM(L6:L19) -> 2 | M20: =SUM(M6:M19) -> 2 | ... AU20: =SUM(AU6:AU19) -> 0
H21: =$E6*H6+$E7*H7+$E8*H8+$E9*H9+$E10*H10+$E11*H11+$E12*H12+$E14*H14+$E15*H15+$E16*H16+$E17*H17+$E18*H18+$E19*H19+$E13*H13 -> 11000 | I21: =$E6*I6+$E7*I7+$E8*I8+$E9*I9+$E10*I10+$E11*I11+$E12*I12+$E14*I14+$E15*I15+$E16*I16+$E17*I17+$E18*I18+$E19*I19+$E13*I13 -> 6000 | J21: =$E6*J6+$E7*J7+$E8*J8+$E9*J9+$E10*J10+$E11*J11+$E12*J12+$E14*J14+$E15*J15+$E16*J16+$E17*J17+$E18*J18+$E19*J19+$E13*J13 -> 6500 | K21: =$E6*K6+$E7*K7+$E8*K8+$E9*K9+$E10*K10+$E11*K11+$E12*K12+$E14*K14+$E15*K15+$E16*K16+$E17*K17+$E18*K18+$E19*K19+$E13*K13 -> 6000 | L21: =$E6*L6+$E7*L7+$E8*L8+$E9*L9+$E10*L10+$E11*L11+$E12*L12+$E14*L14+$E15*L15+$E16*L16+$E17*L17+$E18*L18+$E19*L19+$E13*L13 -> 11000 | M21: =$E6*M6+$E7*M7+$E8*M8+$E9*M9+$E10*M10+$E11*M11+$E12*M12+$E14*M14+$E15*M15+$E16*M16+$E17*M17+$E18*M18+$E19*M19+$E13*M13 -> 14000 | N21: =$E6*N6+$E7*N7+$E8*N8+$E9*N9+$E10*N10+$E11*N11+$E12*N12+$E14*N14+$E15*N15+$E16*N16+$E17*N17+$E18*N18+$E19*N19+$E13*N13 -> 5500 | O21: =$E6*O6+$E7*O7+$E8*O8+$E9*O9+$E10*O10+$E11*O11+$E12*O12+$E14*O14+$E15*O15+$E16*O16+$E17*O17+$E18*O18+$E19*O19+$E13*O13 -> 6500 | ... AU21: =$E6*AU6+$E7*AU7+$E8*AU8+$E9*AU9+$E10*AU10+$E11*AU11+$E12*AU12+$E14*AU14+$E15*AU15+$E16*AU16+$E17*AU17+$E18*AU18+$E19*AU19+$E13*AU13 -> 0

Sheet 2
B2: ■ DAILY MINIBAR SALES
B4: ITEM | C4: EXPIRATION DATE 1 | D4: EXPIRATION DATE 2 | E4: SALES PRICE | F4: TOTAL AMOUNT | G4: No. | H4: 1 | I4: 2 | J4: 3 | K4: 4 | L4: 5 | M4: 6 | N4: 7 | O4: 8 | P4: 9 | Q4: 10 | R4: 11 | S4: 12 | T4: 13 | U4: 14 | V4: 15 | W4: 16 | X4: 17 | Y4: 18 | Z4: 19 | AA4: 20 | AB4: 21 | AC4: 22 | AD4: 23 | AE4: 24 | AF4: 25 | AG4: 26 | AH4: 27 | AI4: 28 | AJ4: 29 | AK4: 30 | AL4: 31 | AM4: 32 | AN4: 33 | AO4: 34 | AP4: 35 | AQ4: 36 | AR4: 37 | AS4: 38 | AT4: 39 | AU4: 40
G5: Room No. | H5: 1001 | I5: 617 | J5: 1018 | K5: 614 | L5: 1230 | M5: 1614 | N5: 1430 | O5: 1120 | P5: 1402 | Q5: 618 | R5: 1125 | S5: 1715 | T5: 1506 | U5: 1414 | V5: 1203 | W5: 724 | X5: 1529 | Y5: 1228 | Z5: 1123 | AA5: 1019
B6: Potato Chip 감자칩 | C6: 2026년11월 | E6: 6000 | F6: =E6*G6 -> 42000 | G6: =SUM(H6:AU6) -> 7 | K6: 1 | M6: 1 | Q6: 1 | S6: 1 | T6: 1 | Z6: 1 | AA6: 1
B7: Haribo Jelly 하리보 | C7: 2026년11월 | E7: 6500 | F7: =E7*G7 -> 26000 | G7: =SUM(H7:AU7) -> 4 | J7: 1 | K7: 1 | O7: 1 | S7: 1
B8: Fried Squid 오징어 | C8: 2026년10월 | D8: 2026년9월 | E8: 7000 | F8: =E8*G8 -> 49000 | G8: =SUM(H8:AU8) -> 7 | H8: 2 | J8: 1 | K8: 1 | P8: 1 | Q8: 1 | AA8: 1
B9: Evian 에비앙 | C9: 2027년08월 | E9: 5500 | F9: =E9*G9 -> 38500 | G9: =SUM(H9:AU9) -> 7 | I9: 1 | K9: 1 | M9: 1 | W9: 1 | Y9: 2 | Z9: 1
B10: Coke 콜라 | C10: 2027년12월 | E10: 4000 | F10: =E10*G10 -> 4000 | G10: =SUM(H10:AU10) -> 1 | X10: 1
B11: Zero Coke 제로 콜라 | C11: 2027년2월 | E11: 4000 | F11: =E11*G11 -> 20000 | G11: =SUM(H11:AU11) -> 5 | K11: 1 | L11: 1 | M11: 1 | Q11: 1 | R11: 1
B12: Sprite 스프라이트 | C12: 2028년1월 | E12: 4000 | F12: =E12*G12 -> 4000 | G12: =SUM(H12:AU12) -> 1 | V12: 1
B13: Red Bull 레드불 | C13: 2027년2월 | E13: 5000 | F13: =E13*G13 -> 0 | G13: =SUM(H13:AU13) -> 0
B14: Budweiser 버드와이저 | C14: 2026년11월 | E14: 7000 | F14: =E14*G14 -> 21000 | G14: =SUM(H14:AU14) -> 3 | K14: 1 | N14: 1 | U14: 1
B15: Cass 카스 | C15: 2027년1월 | E15: 7000 | F15: =E15*G15 -> 35000 | G15: =SUM(H15:AU15) -> 5 | K15: 1 | M15: 1 | T15: 1 | U15: 1 | W15: 1
B16: Despina 데스피나 | E16: 7000 | F16: =E16*G16 -> 0 | G16: =SUM(H16:AU16) -> 0
B17: Neptune Pale Ale 넵튠 에일 | E17: 7000 | F17: =E17*G17 -> 0 | G17: =SUM(H17:AU17) -> 0
B18: Two Face Black IPA 투페이스 | E18: 7000 | F18: =E18*G18 -> 0 | G18: =SUM(H18:AU18) -> 0
B19: No.5 Stout 넘버5 | E19: 7000 | F19: =E19*G19 -> 0 | G19: =SUM(H19:AU19) -> 0
B20: TOTAL | E20: =SUM(E6:E8,E10:E15)+E9*2 -> 61500 | F20: =SUM(F6:F19) -> 239500 | G20: =SUM(G6:G19) -> 40 | H20: =SUM(H6:H19) -> 2 | I20: =SUM(I6:I19) -> 1 | J20: =SUM(J6:J19) -> 2 | K20: =SUM(K6:K19) -> 7 | L20: =SUM(L6:L19) -> 1 | M20: =SUM(M6:M19) -> 4 | ... AU20: =SUM(AU6:AU19) -> 0
H21: =$E6*H6+$E7*H7+$E8*H8+$E9*H9+$E10*H10+$E11*H11+$E12*H12+$E14*H14+$E15*H15+$E16*H16+$E17*H17+$E18*H18+$E19*H19+$E13*H13 -> 14000 | I21: =$E6*I6+$E7*I7+$E8*I8+$E9*I9+$E10*I10+$E11*I11+$E12*I12+$E14*I14+$E15*I15+$E16*I16+$E17*I17+$E18*I18+$E19*I19+$E13*I13 -> 5500 | J21: =$E6*J6+$E7*J7+$E8*J8+$E9*J9+$E10*J10+$E11*J11+$E12*J12+$E14*J14+$E15*J15+$E16*J16+$E17*J17+$E18*J18+$E19*J19+$E13*J13 -> 13500 | K21: =$E6*K6+$E7*K7+$E8*K8+$E9*K9+$E10*K10+$E11*K11+$E12*K12+$E14*K14+$E15*K15+$E16*K16+$E17*K17+$E18*K18+$E19*K19+$E13*K13 -> 43000 | L21: =$E6*L6+$E7*L7+$E8*L8+$E9*L9+$E10*L10+$E11*L11+$E12*L12+$E14*L14+$E15*L15+$E16*L16+$E17*L17+$E18*L18+$E19*L19+$E13*L13 -> 4000 | M21: =$E6*M6+$E7*M7+$E8*M8+$E9*M9+$E10*M10+$E11*M11+$E12*M12+$E14*M14+$E15*M15+$E16*M16+$E17*M17+$E18*M18+$E19*M19+$E13*M13 -> 22500 | N21: =$E6*N6+$E7*N7+$E8*N8+$E9*N9+$E10*N10+$E11*N11+$E12*N12+$E14*N14+$E15*N15+$E16*N16+$E17*N17+$E18*N18+$E19*N19+$E13*N13 -> 7000 | O21: =$E6*O6+$E7*O7+$E8*O8+$E9*O9+$E10*O10+$E11*O11+$E12*O12+$E14*O14+$E15*O15+$E16*O16+$E17*O17+$E18*O18+$E19*O19+$E13*O13 -> 6500 | ... AU21: =$E6*AU6+$E7*AU7+$E8*AU8+$E9*AU9+$E10*AU10+$E11*AU11+$E12*AU12+$E14*AU14+$E15*AU15+$E16*AU16+$E17*AU17+$E18*AU18+$E19*AU19+$E13*AU13 -> 0

Sheet 3
B2: ■ DAILY MINIBAR SALES
B4: ITEM | C4: EXPIRATION DATE 1 | D4: EXPIRATION DATE 2 | E4: SALES PRICE | F4: TOTAL AMOUNT | G4: No. | H4: 1 | I4: 2 | J4: 3 | K4: 4 | L4: 5 | M4: 6 | N4: 7 | O4: 8 | P4: 9 | Q4: 10 | R4: 11 | S4: 12 | T4: 13 | U4: 14 | V4: 15 | W4: 16 | X4: 17 | Y4: 18 | Z4: 19 | AA4: 20 | AB4: 21 | AC4: 22 | AD4: 23 | AE4: 24 | AF4: 25 | AG4: 26 | AH4: 27 | AI4: 28 | AJ4: 29 | AK4: 30 | AL4: 31 | AM4: 32 | AN4: 33 | AO4: 34 | AP4: 35 | AQ4: 36 | AR4: 37 | AS4: 38 | AT4: 39 | AU4: 40
G5: Room No. | H5: 1225 | I5: 505 | J5: 1614 | K5: 1021 | L5: 828 | M5: 928 | N5: 1102 | O5: 926 | P5: 724 | Q5: 1402 | R5: 1716 | S5: 922 | T5: 1425 | U5: 914 | V5: 1519 | W5: 1226 | X5: 1002 | Y5: 1031 | Z5: 1227 | AA5: 706 | AB5: 1506 | AC5: 531 | AD5: 1624 | AE5: 826
B6: Potato Chip 감자칩 | C6: 2026년11월 | E6: 6000 | F6: =E6*G6 -> 30000 | G6: =SUM(H6:AU6) -> 5 | K6: 1 | L6: 1 | T6: 1 | X6: 1 | AC6: 1
B7: Haribo Jelly 하리보 | C7: 2026년11월 | E7: 6500 | F7: =E7*G7 -> 32500 | G7: =SUM(H7:AU7) -> 5 | H7: 1 | K7: 1 | R7: 1 | T7: 1 | AE7: 1
B8: Fried Squid 오징어 | C8: 2026년10월 | E8: 7000 | F8: =E8*G8 -> 14000 | G8: =SUM(H8:AU8) -> 2 | K8: 1 | T8: 1
B9: Evian 에비앙 | C9: 2027년08월 | E9: 5500 | F9: =E9*G9 -> 82500 | G9: =SUM(H9:AU9) -> 15 | I9: 1 | J9: 2 | K9: 2 | M9: 1 | N9: 1 | O9: 1 | U9: 1 | V9: 2 | W9: 1 | Z9: 1 | AA9: 2
B10: Coke 콜라 | C10: 2027년12월 | E10: 4000 | F10: =E10*G10 -> 0 | G10: =SUM(H10:AU10) -> 0
B11: Zero Coke 제로 콜라 | C11: 2027년2월 | E11: 4000 | F11: =E11*G11 -> 40000 | G11: =SUM(H11:AU11) -> 10 | Q11: 1 | Y11: 8 | Z11: 1
B12: Sprite 스프라이트 | C12: 2028년1월 | E12: 4000 | F12: =E12*G12 -> 0 | G12: =SUM(H12:AU12) -> 0
B13: Red Bull 레드불 | C13: 2027년2월 | E13: 5000 | F13: =E13*G13 -> 10000 | G13: =SUM(H13:AU13) -> 2 | P13: 1 | S13: 1
B14: Budweiser 버드와이저 | C14: 2026년11월 | E14: 7000 | F14: =E14*G14 -> 7000 | G14: =SUM(H14:AU14) -> 1 | AB14: 1
B15: Cass 카스 | C15: 2027년1월 | E15: 7000 | F15: =E15*G15 -> 14000 | G15: =SUM(H15:AU15) -> 2 | S15: 1 | AD15: 1
B16: Despina 데스피나 | E16: 7000 | F16: =E16*G16 -> 0 | G16: =SUM(H16:AU16) -> 0
B17: Neptune Pale Ale 넵튠 에일 | E17: 7000 | F17: =E17*G17 -> 0 | G17: =SUM(H17:AU17) -> 0
B18: Two Face Black IPA 투페이스 | E18: 7000 | F18: =E18*G18 -> 0 | G18: =SUM(H18:AU18) -> 0
B19: No.5 Stout 넘버5 | E19: 7000 | F19: =E19*G19 -> 0 | G19: =SUM(H19:AU19) -> 0
B20: TOTAL | E20: =SUM(E6:E8,E10:E15)+E9*2 -> 61500 | F20: =SUM(F6:F19) -> 230000 | G20: =SUM(G6:G19) -> 42 | H20: =SUM(H6:H19) -> 1 | I20: =SUM(I6:I19) -> 1 | J20: =SUM(J6:J19) -> 2 | K20: =SUM(K6:K19) -> 5 | L20: =SUM(L6:L19) -> 1 | M20: =SUM(M6:M19) -> 1 | ... AU20: =SUM(AU6:AU19) -> 0
H21: =$E6*H6+$E7*H7+$E8*H8+$E9*H9+$E10*H10+$E11*H11+$E12*H12+$E14*H14+$E15*H15+$E16*H16+$E17*H17+$E18*H18+$E19*H19+$E13*H13 -> 6500 | I21: =$E6*I6+$E7*I7+$E8*I8+$E9*I9+$E10*I10+$E11*I11+$E12*I12+$E14*I14+$E15*I15+$E16*I16+$E17*I17+$E18*I18+$E19*I19+$E13*I13 -> 5500 | J21: =$E6*J6+$E7*J7+$E8*J8+$E9*J9+$E10*J10+$E11*J11+$E12*J12+$E14*J14+$E15*J15+$E16*J16+$E17*J17+$E18*J18+$E19*J19+$E13*J13 -> 11000 | K21: =$E6*K6+$E7*K7+$E8*K8+$E9*K9+$E10*K10+$E11*K11+$E12*K12+$E14*K14+$E15*K15+$E16*K16+$E17*K17+$E18*K18+$E19*K19+$E13*K13 -> 30500 | L21: =$E6*L6+$E7*L7+$E8*L8+$E9*L9+$E10*L10+$E11*L11+$E12*L12+$E14*L14+$E15*L15+$E16*L16+$E17*L17+$E18*L18+$E19*L19+$E13*L13 -> 6000 | M21: =$E6*M6+$E7*M7+$E8*M8+$E9*M9+$E10*M10+$E11*M11+$E12*M12+$E14*M14+$E15*M15+$E16*M16+$E17*M17+$E18*M18+$E19*M19+$E13*M13 -> 5500 | N21: =$E6*N6+$E7*N7+$E8*N8+$E9*N9+$E10*N10+$E11*N11+$E12*N12+$E14*N14+$E15*N15+$E16*N16+$E17*N17+$E18*N18+$E19*N19+$E13*N13 -> 5500 | O21: =$E6*O6+$E7*O7+$E8*O8+$E9*O9+$E10*O10+$E11*O11+$E12*O12+$E14*O14+$E15*O15+$E16*O16+$E17*O17+$E18*O18+$E19*O19+$E13*O13 -> 5500 | ... AU21: =$E6*AU6+$E7*AU7+$E8*AU8+$E9*AU9+$E10*AU10+$E11*AU11+$E12*AU12+$E14*AU14+$E15*AU15+$E16*AU16+$E17*AU17+$E18*AU18+$E19*AU19+$E13*AU13 -> 0

Sheet 4
B2: ■ DAILY MINIBAR SALES
B4: ITEM | C4: EXPIRATION DATE 1 | D4: EXPIRATION DATE 2 | E4: SALES PRICE | F4: TOTAL AMOUNT | G4: No. | H4: 1 | I4: 2 | J4: 3 | K4: 4 | L4: 5 | M4: 6 | N4: 7 | O4: 8 | P4: 9 | Q4: 10 | R4: 11 | S4: 12 | T4: 13 | U4: 14 | V4: 15 | W4: 16 | X4: 17 | Y4: 18 | Z4: 19 | AA4: 20 | AB4: 21 | AC4: 22 | AD4: 23 | AE4: 24 | AF4: 25 | AG4: 26 | AH4: 27 | AI4: 28 | AJ4: 29 | AK4: 30 | AL4: 31 | AM4: 32 | AN4: 33 | AO4: 34 | AP4: 35 | AQ4: 36 | AR4: 37 | AS4: 38 | AT4: 39 | AU4: 40
G5: Room No. | H5: 1801 | I5: 1528 | J5: 1614 | K5: 712 | L5: 1102 | M5: 1402 | N5: 801 | O5: 1230 | P5: 722 | Q5: 1024 | R5: 619 | S5: 616 | T5: 1025 | U5: 618 | V5: 1127 | W5: 1726 | X5: 1125 | Y5: 922 | Z5: 1129 | AA5: 1622 | AB5: 821 | AC5: 1805 | AD5: 726
B6: Potato Chip 감자칩 | C6: 2026년11월 | E6: 6000 | F6: =E6*G6 -> 42000 | G6: =SUM(H6:AU6) -> 7 | J6: 1 | M6: 1 | P6: 1 | R6: 1 | U6: 1 | X6: 1 | AC6: 1
B7: Haribo Jelly 하리보 | C7: 2026년11월 | E7: 6500 | F7: =E7*G7 -> 45500 | G7: =SUM(H7:AU7) -> 7 | K7: 1 | Q7: 1 | V7: 1 | W7: 1 | X7: 1 | Y7: 1 | AC7: 1
B8: Fried Squid 오징어 | C8: 2026년10월 | E8: 7000 | F8: =E8*G8 -> 14000 | G8: =SUM(H8:AU8) -> 2 | U8: 1 | AC8: 1
B9: Evian 에비앙 | C9: 2027년08월 | E9: 5500 | F9: =E9*G9 -> 99000 | G9: =SUM(H9:AU9) -> 18 | H9: 4 | I9: 1 | J9: 2 | L9: 2 | N9: 1 | R9: 1 | S9: 1 | U9: 1 | X9: 2 | AA9: 2 | AB9: 1
B10: Coke 콜라 | C10: 2027년12월 | E10: 4000 | F10: =E10*G10 -> 16000 | G10: =SUM(H10:AU10) -> 4 | M10: 1 | T10: 1 | X10: 1 | AB10: 1
B11: Zero Coke 제로 콜라 | C11: 2027년2월 | E11: 4000 | F11: =E11*G11 -> 16000 | G11: =SUM(H11:AU11) -> 4 | O11: 1 | R11: 1 | U11: 1 | X11: 1
B12: Sprite 스프라이트 | C12: 2028년1월 | E12: 4000 | F12: =E12*G12 -> 12000 | G12: =SUM(H12:AU12) -> 3 | V12: 1 | AA12: 1 | AB12: 1
B13: Red Bull 레드불 | C13: 2027년2월 | E13: 5000 | F13: =E13*G13 -> 5000 | G13: =SUM(H13:AU13) -> 1 | AD13: 1
B14: Budweiser 버드와이저 | C14: 2026년11월 | E14: 7000 | F14: =E14*G14 -> 7000 | G14: =SUM(H14:AU14) -> 1 | AA14: 1
B15: Cass 카스 | C15: 2027년1월 | E15: 7000 | F15: =E15*G15 -> 21000 | G15: =SUM(H15:AU15) -> 3 | J15: 1 | Z15: 1 | AA15: 1
B16: Despina 데스피나 | E16: 7000 | F16: =E16*G16 -> 0 | G16: =SUM(H16:AU16) -> 0
B17: Neptune Pale Ale 넵튠 에일 | E17: 7000 | F17: =E17*G17 -> 0 | G17: =SUM(H17:AU17) -> 0
B18: Two Face Black IPA 투페이스 | E18: 7000 | F18: =E18*G18 -> 0 | G18: =SUM(H18:AU18) -> 0
B19: No.5 Stout 넘버5 | E19: 7000 | F19: =E19*G19 -> 0 | G19: =SUM(H19:AU19) -> 0
B20: TOTAL | E20: =SUM(E6:E8,E10:E15)+E9*2 -> 61500 | F20: =SUM(F6:F19) -> 277500 | G20: =SUM(G6:G19) -> 50 | H20: =SUM(H6:H19) -> 4 | I20: =SUM(I6:I19) -> 1 | J20: =SUM(J6:J19) -> 4 | K20: =SUM(K6:K19) -> 1 | L20: =SUM(L6:L19) -> 2 | M20: =SUM(M6:M19) -> 2 | ... AU20: =SUM(AU6:AU19) -> 0
H21: =$E6*H6+$E7*H7+$E8*H8+$E9*H9+$E10*H10+$E11*H11+$E12*H12+$E14*H14+$E15*H15+$E16*H16+$E17*H17+$E18*H18+$E19*H19+$E13*H13 -> 22000 | I21: =$E6*I6+$E7*I7+$E8*I8+$E9*I9+$E10*I10+$E11*I11+$E12*I12+$E14*I14+$E15*I15+$E16*I16+$E17*I17+$E18*I18+$E19*I19+$E13*I13 -> 5500 | J21: =$E6*J6+$E7*J7+$E8*J8+$E9*J9+$E10*J10+$E11*J11+$E12*J12+$E14*J14+$E15*J15+$E16*J16+$E17*J17+$E18*J18+$E19*J19+$E13*J13 -> 24000 | K21: =$E6*K6+$E7*K7+$E8*K8+$E9*K9+$E10*K10+$E11*K11+$E12*K12+$E14*K14+$E15*K15+$E16*K16+$E17*K17+$E18*K18+$E19*K19+$E13*K13 -> 6500 | L21: =$E6*L6+$E7*L7+$E8*L8+$E9*L9+$E10*L10+$E11*L11+$E12*L12+$E14*L14+$E15*L15+$E16*L16+$E17*L17+$E18*L18+$E19*L19+$E13*L13 -> 11000 | M21: =$E6*M6+$E7*M7+$E8*M8+$E9*M9+$E10*M10+$E11*M11+$E12*M12+$E14*M14+$E15*M15+$E16*M16+$E17*M17+$E18*M18+$E19*M19+$E13*M13 -> 10000 | N21: =$E6*N6+$E7*N7+$E8*N8+$E9*N9+$E10*N10+$E11*N11+$E12*N12+$E14*N14+$E15*N15+$E16*N16+$E17*N17+$E18*N18+$E19*N19+$E13*N13 -> 5500 | O21: =$E6*O6+$E7*O7+$E8*O8+$E9*O9+$E10*O10+$E11*O11+$E12*O12+$E14*O14+$E15*O15+$E16*O16+$E17*O17+$E18*O18+$E19*O19+$E13*O13 -> 4000 | ... AU21: =$E6*AU6+$E7*AU7+$E8*AU8+$E9*AU9+$E10*AU10+$E11*AU11+$E12*AU12+$E14*AU14+$E15*AU15+$E16*AU16+$E17*AU17+$E18*AU18+$E19*AU19+$E13*AU13 -> 0

Sheet 5
B2: ■ DAILY MINIBAR SALES
B4: ITEM | C4: EXPIRATION DATE 1 | D4: EXPIRATION DATE 2 | E4: SALES PRICE | F4: TOTAL AMOUNT | G4: No. | H4: 1 | I4: 2 | J4: 3 | K4: 4 | L4: 5 | M4: 6 | N4: 7 | O4: 8 | P4: 9 | Q4: 10 | R4: 11 | S4: 12 | T4: 13 | U4: 14 | V4: 15 | W4: 16 | X4: 17 | Y4: 18 | Z4: 19 | AA4: 20 | AB4: 21 | AC4: 22 | AD4: 23 | AE4: 24 | AF4: 25 | AG4: 26 | AH4: 27 | AI4: 28 | AJ4: 29 | AK4: 30 | AL4: 31 | AM4: 32 | AN4: 33 | AO4: 34 | AP4: 35 | AQ4: 36 | AR4: 37 | AS4: 38 | AT4: 39 | AU4: 40
G5: Room No. | H5: 824 | I5: 509 | J5: 617 | K5: 1221 | L5: 1807 | M5: 615(콤프) | N5: 1102 | O5: 1123 | P5: 1717 | Q5: 508 | R5: 1702 | S5: 720 | T5: 714 | U5: 1506 | V5: 618 | W5: 818 | X5: 1720 | Y5: 611
B6: Potato Chip 감자칩 | C6: 2026년11월 | E6: 6000 | F6: =E6*G6 -> 24000 | G6: =SUM(H6:AU6) -> 4 | K6: 1 | O6: 1 | U6: 1 | W6: 1
B7: Haribo Jelly 하리보 | C7: 2026년11월 | E7: 6500 | F7: =E7*G7 -> 6500 | G7: =SUM(H7:AU7) -> 1 | T7: 1
B8: Fried Squid 오징어 | C8: 2026년12월 | D8: 2026년7월 | E8: 7000 | F8: =E8*G8 -> 7000 | G8: =SUM(H8:AU8) -> 1 | T8: 1
B9: Evian 에비앙 | C9: 2027년08월 | E9: 5500 | F9: =E9*G9 -> 88000 | G9: =SUM(H9:AU9) -> 16 | H9: 1 | I9: 1 | J9: 2 | L9: 1 | N9: 2 | O9: 2 | P9: 2 | Q9: 2 | V9: 2 | X9: 1
B10: Coke 콜라 | C10: 2027년12월 | E10: 4000 | F10: =E10*G10 -> 4000 | G10: =SUM(H10:AU10) -> 1 | M10: 1
B11: Zero Coke 제로 콜라 | C11: 2027년2월 | E11: 4000 | F11: =E11*G11 -> 4000 | G11: =SUM(H11:AU11) -> 1 | T11: 1
B12: Sprite 스프라이트 | C12: 2028년1월 | E12: 4000 | F12: =E12*G12 -> 8000 | G12: =SUM(H12:AU12) -> 2 | S12: 1 | Y12: 1
B13: Red Bull 레드불 | C13: 2027년2월 | E13: 5000 | F13: =E13*G13 -> 10000 | G13: =SUM(H13:AU13) -> 2 | R13: 1 | X13: 1
B14: Budweiser 버드와이저 | C14: 2026년11월 | E14: 7000 | F14: =E14*G14 -> 7000 | G14: =SUM(H14:AU14) -> 1 | Q14: 1
B15: Cass 카스 | C15: 2027년1월 | E15: 7000 | F15: =E15*G15 -> 0 | G15: =SUM(H15:AU15) -> 0
B16: Despina 데스피나 | E16: 7000 | F16: =E16*G16 -> 0 | G16: =SUM(H16:AU16) -> 0
B17: Neptune Pale Ale 넵튠 에일 | E17: 7000 | F17: =E17*G17 -> 0 | G17: =SUM(H17:AU17) -> 0
B18: Two Face Black IPA 투페이스 | E18: 7000 | F18: =E18*G18 -> 0 | G18: =SUM(H18:AU18) -> 0
B19: No.5 Stout 넘버5 | E19: 7000 | F19: =E19*G19 -> 0 | G19: =SUM(H19:AU19) -> 0
B20: TOTAL | E20: =SUM(E6:E8,E10:E15)+E9*2 -> 61500 | F20: =SUM(F6:F19) -> 158500 | G20: =SUM(G6:G19) -> 29 | H20: =SUM(H6:H19) -> 1 | I20: =SUM(I6:I19) -> 1 | J20: =SUM(J6:J19) -> 2 | K20: =SUM(K6:K19) -> 1 | L20: =SUM(L6:L19) -> 1 | M20: =SUM(M6:M19) -> 1 | ... AU20: =SUM(AU6:AU19) -> 0
H21: =$E6*H6+$E7*H7+$E8*H8+$E9*H9+$E10*H10+$E11*H11+$E12*H12+$E14*H14+$E15*H15+$E16*H16+$E17*H17+$E18*H18+$E19*H19+$E13*H13 -> 5500 | I21: =$E6*I6+$E7*I7+$E8*I8+$E9*I9+$E10*I10+$E11*I11+$E12*I12+$E14*I14+$E15*I15+$E16*I16+$E17*I17+$E18*I18+$E19*I19+$E13*I13 -> 5500 | J21: =$E6*J6+$E7*J7+$E8*J8+$E9*J9+$E10*J10+$E11*J11+$E12*J12+$E14*J14+$E15*J15+$E16*J16+$E17*J17+$E18*J18+$E19*J19+$E13*J13 -> 11000 | K21: =$E6*K6+$E7*K7+$E8*K8+$E9*K9+$E10*K10+$E11*K11+$E12*K12+$E14*K14+$E15*K15+$E16*K16+$E17*K17+$E18*K18+$E19*K19+$E13*K13 -> 6000 | L21: =$E6*L6+$E7*L7+$E8*L8+$E9*L9+$E10*L10+$E11*L11+$E12*L12+$E14*L14+$E15*L15+$E16*L16+$E17*L17+$E18*L18+$E19*L19+$E13*L13 -> 5500 | M21: =$E6*M6+$E7*M7+$E8*M8+$E9*M9+$E10*M10+$E11*M11+$E12*M12+$E14*M14+$E15*M15+$E16*M16+$E17*M17+$E18*M18+$E19*M19+$E13*M13 -> 4000 | N21: =$E6*N6+$E7*N7+$E8*N8+$E9*N9+$E10*N10+$E11*N11+$E12*N12+$E14*N14+$E15*N15+$E16*N16+$E17*N17+$E18*N18+$E19*N19+$E13*N13 -> 11000 | O21: =$E6*O6+$E7*O7+$E8*O8+$E9*O9+$E10*O10+$E11*O11+$E12*O12+$E14*O14+$E15*O15+$E16*O16+$E17*O17+$E18*O18+$E19*O19+$E13*O13 -> 17000 | ... AU21: =$E6*AU6+$E7*AU7+$E8*AU8+$E9*AU9+$E10*AU10+$E11*AU11+$E12*AU12+$E14*AU14+$E15*AU15+$E16*AU16+$E17*AU17+$E18*AU18+$E19*AU19+$E13*AU13 -> 0

Sheet 6
B2: ■ DAILY MINIBAR SALES
B4: ITEM | C4: EXPIRATION DATE 1 | D4: EXPIRATION DATE 2 | E4: SALES PRICE | F4: TOTAL AMOUNT | G4: No. | H4: 1 | I4: 2 | J4: 3 | K4: 4 | L4: 5 | M4: 6 | N4: 7 | O4: 8 | P4: 9 | Q4: 10 | R4: 11 | S4: 12 | T4: 13 | U4: 14 | V4: 15 | W4: 16 | X4: 17 | Y4: 18 | Z4: 19 | AA4: 20 | AB4: 21 | AC4: 22 | AD4: 23 | AE4: 24 | AF4: 25 | AG4: 26 | AH4: 27 | AI4: 28 | AJ4: 29 | AK4: 30 | AL4: 31 | AM4: 32 | AN4: 33 | AO4: 34 | AP4: 35 | AQ4: 36 | AR4: 37 | AS4: 38 | AT4: 39 | AU4: 40
G5: Room No. | H5: 1401 | I5: 827 | J5: 627 | K5: 1701 | L5: 1429 | M5: 824 | N5: 710 | O5: 1806 | P5: 1731 | Q5: 611 | R5: 1102 | S5: 714 | T5: 1622 | U5: 1228 | V5: 717 | W5: 1014 | X5: 1631 | Y5: 1723 | Z5: 1415 | AA5: 1220 | AB5: 1726
B6: Potato Chip 감자칩 | C6: 2026년11월 | E6: 6000 | F6: =E6*G6 -> 18000 | G6: =SUM(H6:AU6) -> 3 | L6: 1 | S6: 1 | AB6: 1
B7: Haribo Jelly 하리보 | C7: 2026년11월 | E7: 6500 | F7: =E7*G7 -> 19500 | G7: =SUM(H7:AU7) -> 3 | S7: 1 | AA7: 1 | AB7: 1
B8: Fried Squid 오징어 | C8: 2026년7월 | E8: 7000 | F8: =E8*G8 -> 7000 | G8: =SUM(H8:AU8) -> 1 | X8: 1
B9: Evian 에비앙 | C9: 2027년08월 | E9: 5500 | F9: =E9*G9 -> 115500 | G9: =SUM(H9:AU9) -> 21 | H9: 2 | J9: 1 | K9: 1 | L9: 1 | M9: 2 | O9: 2 | P9: 1 | R9: 2 | S9: 2 | T9: 1 | U9: 1 | V9: 2 | W9: 2 | X9: 1
B10: Coke 콜라 | C10: 2027년12월 | E10: 4000 | F10: =E10*G10 -> 12000 | G10: =SUM(H10:AU10) -> 3 | O10: 1 | S10: 1 | V10: 1
B11: Zero Coke 제로 콜라 | C11: 2027년2월 | E11: 4000 | F11: =E11*G11 -> 16000 | G11: =SUM(H11:AU11) -> 4 | L11: 1 | N11: 1 | Q11: 1 | Y11: 1
B12: Sprite 스프라이트 | C12: 2028년1월 | E12: 4000 | F12: =E12*G12 -> 8000 | G12: =SUM(H12:AU12) -> 2 | I12: 1 | X12: 1
B13: Red Bull 레드불 | C13: 2027년2월 | E13: 5000 | F13: =E13*G13 -> 0 | G13: =SUM(H13:AU13) -> 0
B14: Budweiser 버드와이저 | C14: 2026년11월 | E14: 7000 | F14: =E14*G14 -> 7000 | G14: =SUM(H14:AU14) -> 1 | X14: 1
B15: Cass 카스 | C15: 2027년1월 | D15: 2027년3월 | E15: 7000 | F15: =E15*G15 -> 14000 | G15: =SUM(H15:AU15) -> 2 | X15: 1 | Z15: 1
B16: Despina 데스피나 | E16: 7000 | F16: =E16*G16 -> 0 | G16: =SUM(H16:AU16) -> 0
B17: Neptune Pale Ale 넵튠 에일 | E17: 7000 | F17: =E17*G17 -> 0 | G17: =SUM(H17:AU17) -> 0
B18: Two Face Black IPA 투페이스 | E18: 7000 | F18: =E18*G18 -> 0 | G18: =SUM(H18:AU18) -> 0
B19: No.5 Stout 넘버5 | E19: 7000 | F19: =E19*G19 -> 0 | G19: =SUM(H19:AU19) -> 0
B20: TOTAL | E20: =SUM(E6:E8,E10:E15)+E9*2 -> 61500 | F20: =SUM(F6:F19) -> 217000 | G20: =SUM(G6:G19) -> 40 | H20: =SUM(H6:H19) -> 2 | I20: =SUM(I6:I19) -> 1 | J20: =SUM(J6:J19) -> 1 | K20: =SUM(K6:K19) -> 1 | L20: =SUM(L6:L19) -> 3 | M20: =SUM(M6:M19) -> 2 | ... AU20: =SUM(AU6:AU19) -> 0
H21: =$E6*H6+$E7*H7+$E8*H8+$E9*H9+$E10*H10+$E11*H11+$E12*H12+$E14*H14+$E15*H15+$E16*H16+$E17*H17+$E18*H18+$E19*H19+$E13*H13 -> 11000 | I21: =$E6*I6+$E7*I7+$E8*I8+$E9*I9+$E10*I10+$E11*I11+$E12*I12+$E14*I14+$E15*I15+$E16*I16+$E17*I17+$E18*I18+$E19*I19+$E13*I13 -> 4000 | J21: =$E6*J6+$E7*J7+$E8*J8+$E9*J9+$E10*J10+$E11*J11+$E12*J12+$E14*J14+$E15*J15+$E16*J16+$E17*J17+$E18*J18+$E19*J19+$E13*J13 -> 5500 | K21: =$E6*K6+$E7*K7+$E8*K8+$E9*K9+$E10*K10+$E11*K11+$E12*K12+$E14*K14+$E15*K15+$E16*K16+$E17*K17+$E18*K18+$E19*K19+$E13*K13 -> 5500 | L21: =$E6*L6+$E7*L7+$E8*L8+$E9*L9+$E10*L10+$E11*L11+$E12*L12+$E14*L14+$E15*L15+$E16*L16+$E17*L17+$E18*L18+$E19*L19+$E13*L13 -> 15500 | M21: =$E6*M6+$E7*M7+$E8*M8+$E9*M9+$E10*M10+$E11*M11+$E12*M12+$E14*M14+$E15*M15+$E16*M16+$E17*M17+$E18*M18+$E19*M19+$E13*M13 -> 11000 | N21: =$E6*N6+$E7*N7+$E8*N8+$E9*N9+$E10*N10+$E11*N11+$E12*N12+$E14*N14+$E15*N15+$E16*N16+$E17*N17+$E18*N18+$E19*N19+$E13*N13 -> 4000 | O21: =$E6*O6+$E7*O7+$E8*O8+$E9*O9+$E10*O10+$E11*O11+$E12*O12+$E14*O14+$E15*O15+$E16*O16+$E17*O17+$E18*O18+$E19*O19+$E13*O13 -> 15000 | ... AU21: =$E6*AU6+$E7*AU7+$E8*AU8+$E9*AU9+$E10*AU10+$E11*AU11+$E12*AU12+$E14*AU14+$E15*AU15+$E16*AU16+$E17*AU17+$E18*AU18+$E19*AU19+$E13*AU13 -> 0

Sheet 7
B2: ■ DAILY MINIBAR SALES
B4: ITEM | C4: EXPIRATION DATE 1 | D4: EXPIRATION DATE 2 | E4: SALES PRICE | F4: TOTAL AMOUNT | G4: No. | H4: 1 | I4: 2 | J4: 3 | K4: 4 | L4: 5 | M4: 6 | N4: 7 | O4: 8 | P4: 9 | Q4: 10 | R4: 11 | S4: 12 | T4: 13 | U4: 14 | V4: 15 | W4: 16 | X4: 17 | Y4: 18 | Z4: 19 | AA4: 20 | AB4: 21 | AC4: 22 | AD4: 23 | AE4: 24 | AF4: 25 | AG4: 26 | AH4: 27 | AI4: 28 | AJ4: 29 | AK4: 30 | AL4: 31 | AM4: 32 | AN4: 33 | AO4: 34 | AP4: 35 | AQ4: 36 | AR4: 37 | AS4: 38 | AT4: 39 | AU4: 40
G5: Room No. | H5: 931 | I5: 1127 | J5: 1506 | K5: 1425 | L5: 1626 | M5: 1015 | N5: 824 | O5: 1206 | P5: 1415 | Q5: 1018 | R5: 1717 | S5: 1525 | T5: 1223 | U5: 1103 | V5: 611 | W5: 1029 | X5: 916 | Y5: 1605 | Z5: 1030 | AA5: 1406 | AB5: 717 | AC5: 1229 | AD5: 706 | AE5: 1121 | AF5: 1130 | AG5: 617
B6: Potato Chip 감자칩 | C6: 2026년11월 | E6: 6000 | F6: =E6*G6 -> 12000 | G6: =SUM(H6:AU6) -> 2 | AB6: 1 | AF6: 1
B7: Haribo Jelly 하리보 | C7: 2026년11월 | E7: 6500 | F7: =E7*G7 -> 26000 | G7: =SUM(H7:AU7) -> 4 | J7: 1 | M7: 1 | X7: 1 | AD7: 1
B8: Fried Squid 오징어 | C8: 2026년7월 | E8: 7000 | F8: =E8*G8 -> 35000 | G8: =SUM(H8:AU8) -> 5 | M8: 1 | N8: 1 | O8: 1 | AB8: 1 | AD8: 1
B9: Evian 에비앙 | C9: 2027년08월 | E9: 5500 | F9: =E9*G9 -> 88000 | G9: =SUM(H9:AU9) -> 16 | M9: 1 | P9: 1 | Q9: 2 | R9: 2 | S9: 1 | U9: 1 | V9: 2 | W9: 1 | AA9: 1 | AB9: 2 | AC9: 1 | AG9: 1
B10: Coke 콜라 | C10: 2027년12월 | E10: 4000 | F10: =E10*G10 -> 12000 | G10: =SUM(H10:AU10) -> 3 | K10: 1 | Y10: 1 | Z10: 1
B11: Zero Coke 제로 콜라 | C11: 2027년2월 | E11: 4000 | F11: =E11*G11 -> 4000 | G11: =SUM(H11:AU11) -> 1 | K11: 1
B12: Sprite 스프라이트 | C12: 2028년1월 | E12: 4000 | F12: =E12*G12 -> 4000 | G12: =SUM(H12:AU12) -> 1 | L12: 1
B13: Red Bull 레드불 | C13: 2027년2월 | E13: 5000 | F13: =E13*G13 -> 0 | G13: =SUM(H13:AU13) -> 0
B14: Budweiser 버드와이저 | C14: 2026년11월 | E14: 7000 | F14: =E14*G14 -> 21000 | G14: =SUM(H14:AU14) -> 3 | I14: 1 | O14: 1 | AG14: 1
B15: Cass 카스 | C15: 2027년3월 | E15: 7000 | F15: =E15*G15 -> 28000 | G15: =SUM(H15:AU15) -> 4 | H15: 1 | T15: 1 | Y15: 1 | AE15: 1
B16: Despina 데스피나 | E16: 7000 | F16: =E16*G16 -> 0 | G16: =SUM(H16:AU16) -> 0
B17: Neptune Pale Ale 넵튠 에일 | E17: 7000 | F17: =E17*G17 -> 0 | G17: =SUM(H17:AU17) -> 0
B18: Two Face Black IPA 투페이스 | E18: 7000 | F18: =E18*G18 -> 0 | G18: =SUM(H18:AU18) -> 0
B19: No.5 Stout 넘버5 | E19: 7000 | F19: =E19*G19 -> 0 | G19: =SUM(H19:AU19) -> 0
B20: TOTAL | E20: =SUM(E6:E8,E10:E15)+E9*2 -> 61500 | F20: =SUM(F6:F19) -> 230000 | G20: =SUM(G6:G19) -> 39 | H20: =SUM(H6:H19) -> 1 | I20: =SUM(I6:I19) -> 1 | J20: =SUM(J6:J19) -> 1 | K20: =SUM(K6:K19) -> 2 | L20: =SUM(L6:L19) -> 1 | M20: =SUM(M6:M19) -> 3 | ... AU20: =SUM(AU6:AU19) -> 0
H21: =$E6*H6+$E7*H7+$E8*H8+$E9*H9+$E10*H10+$E11*H11+$E12*H12+$E14*H14+$E15*H15+$E16*H16+$E17*H17+$E18*H18+$E19*H19+$E13*H13 -> 7000 | I21: =$E6*I6+$E7*I7+$E8*I8+$E9*I9+$E10*I10+$E11*I11+$E12*I12+$E14*I14+$E15*I15+$E16*I16+$E17*I17+$E18*I18+$E19*I19+$E13*I13 -> 7000 | J21: =$E6*J6+$E7*J7+$E8*J8+$E9*J9+$E10*J10+$E11*J11+$E12*J12+$E14*J14+$E15*J15+$E16*J16+$E17*J17+$E18*J18+$E19*J19+$E13*J13 -> 6500 | K21: =$E6*K6+$E7*K7+$E8*K8+$E9*K9+$E10*K10+$E11*K11+$E12*K12+$E14*K14+$E15*K15+$E16*K16+$E17*K17+$E18*K18+$E19*K19+$E13*K13 -> 8000 | L21: =$E6*L6+$E7*L7+$E8*L8+$E9*L9+$E10*L10+$E11*L11+$E12*L12+$E14*L14+$E15*L15+$E16*L16+$E17*L17+$E18*L18+$E19*L19+$E13*L13 -> 4000 | M21: =$E6*M6+$E7*M7+$E8*M8+$E9*M9+$E10*M10+$E11*M11+$E12*M12+$E14*M14+$E15*M15+$E16*M16+$E17*M17+$E18*M18+$E19*M19+$E13*M13 -> 19000 | N21: =$E6*N6+$E7*N7+$E8*N8+$E9*N9+$E10*N10+$E11*N11+$E12*N12+$E14*N14+$E15*N15+$E16*N16+$E17*N17+$E18*N18+$E19*N19+$E13*N13 -> 7000 | O21: =$E6*O6+$E7*O7+$E8*O8+$E9*O9+$E10*O10+$E11*O11+$E12*O12+$E14*O14+$E15*O15+$E16*O16+$E17*O17+$E18*O18+$E19*O19+$E13*O13 -> 14000 | ... AU21: =$E6*AU6+$E7*AU7+$E8*AU8+$E9*AU9+$E10*AU10+$E11*AU11+$E12*AU12+$E14*AU14+$E15*AU15+$E16*AU16+$E17*AU17+$E18*AU18+$E19*AU19+$E13*AU13 -> 0

Sheet 8
B2: ■ DAILY MINIBAR SALES
B4: ITEM | C4: EXPIRATION DATE 1 | D4: EXPIRATION DATE 2 | E4: SALES PRICE | F4: TOTAL AMOUNT | G4: No. | H4: 1 | I4: 2 | J4: 3 | K4: 4 | L4: 5 | M4: 6 | N4: 7 | O4: 8 | P4: 9 | Q4: 10 | R4: 11 | S4: 12 | T4: 13 | U4: 14 | V4: 15 | W4: 16 | X4: 17 | Y4: 18 | Z4: 19 | AA4: 20 | AB4: 21 | AC4: 22 | AD4: 23 | AE4: 24 | AF4: 25 | AG4: 26 | AH4: 27 | AI4: 28 | AJ4: 29 | AK4: 30 | AL4: 31 | AM4: 32 | AN4: 33 | AO4: 34 | AP4: 35 | AQ4: 36 | AR4: 37 | AS4: 38 | AT4: 39 | AU4: 40
G5: Room No. | H5: 1531 | I5: 1414 | J5: 1130 | K5: 916 | L5: 926 | M5: 611 | N5: 509 | O5: 1022 | P5: 1614 | Q5: 728 | R5: 1121 | S5: 1118 | T5: 1622 | U5: 1415 | V5: 1029 | W5: 1717 | X5: 1102 | Y5: 1219 | Z5: 717 | AA5: 710 | AB5: 726 | AC5: 1731 | AD5: 1714
B6: Potato Chip 감자칩 | C6: 2026년11월 | E6: 6000 | F6: =E6*G6 -> 36000 | G6: =SUM(H6:AU6) -> 6 | J6: 1 | L6: 1 | R6: 1 | S6: 1 | Y6: 1 | AD6: 1
B7: Haribo Jelly 하리보 | C7: 2026년11월 | E7: 6500 | F7: =E7*G7 -> 19500 | G7: =SUM(H7:AU7) -> 3 | U7: 1 | V7: 1 | AA7: 1
B8: Fried Squid 오징어 | C8: 2026년7월 | E8: 7000 | F8: =E8*G8 -> 7000 | G8: =SUM(H8:AU8) -> 1 | H8: 1
B9: Evian 에비앙 | C9: 2027년08월 | E9: 5500 | F9: =E9*G9 -> 110000 | G9: =SUM(H9:AU9) -> 20 | K9: 1 | M9: 2 | N9: 1 | O9: 2 | P9: 1 | R9: 1 | T9: 2 | W9: 2 | X9: 2 | Y9: 2 | Z9: 2 | AA9: 1 | AC9: 1
B10: Coke 콜라 | C10: 2027년12월 | E10: 4000 | F10: =E10*G10 -> 12000 | G10: =SUM(H10:AU10) -> 3 | Q10: 1 | Z10: 1 | AC10: 1
B11: Zero Coke 제로 콜라 | C11: 2027년2월 | E11: 4000 | F11: =E11*G11 -> 16000 | G11: =SUM(H11:AU11) -> 4 | N11: 1 | W11: 1 | AA11: 1 | AC11: 1
B12: Sprite 스프라이트 | C12: 2028년1월 | E12: 4000 | F12: =E12*G12 -> 4000 | G12: =SUM(H12:AU12) -> 1 | AA12: 1
B13: Red Bull 레드불 | C13: 2027년2월 | E13: 5000 | F13: =E13*G13 -> 10000 | G13: =SUM(H13:AU13) -> 2 | I13: 1 | AB13: 1
B14: Budweiser 버드와이저 | C14: 2026년11월 | E14: 7000 | F14: =E14*G14 -> 7000 | G14: =SUM(H14:AU14) -> 1 | R14: 1
B15: Cass 카스 | C15: 2027년3월 | E15: 7000 | F15: =E15*G15 -> 7000 | G15: =SUM(H15:AU15) -> 1 | R15: 1
B16: Despina 데스피나 | E16: 7000 | F16: =E16*G16 -> 0 | G16: =SUM(H16:AU16) -> 0
B17: Neptune Pale Ale 넵튠 에일 | E17: 7000 | F17: =E17*G17 -> 0 | G17: =SUM(H17:AU17) -> 0
B18: Two Face Black IPA 투페이스 | E18: 7000 | F18: =E18*G18 -> 0 | G18: =SUM(H18:AU18) -> 0
B19: No.5 Stout 넘버5 | E19: 7000 | F19: =E19*G19 -> 0 | G19: =SUM(H19:AU19) -> 0
B20: TOTAL | E20: =SUM(E6:E8,E10:E15)+E9*2 -> 61500 | F20: =SUM(F6:F19) -> 228500 | G20: =SUM(G6:G19) -> 42 | H20: =SUM(H6:H19) -> 1 | I20: =SUM(I6:I19) -> 1 | J20: =SUM(J6:J19) -> 1 | K20: =SUM(K6:K19) -> 1 | L20: =SUM(L6:L19) -> 1 | M20: =SUM(M6:M19) -> 2 | ... AU20: =SUM(AU6:AU19) -> 0
H21: =$E6*H6+$E7*H7+$E8*H8+$E9*H9+$E10*H10+$E11*H11+$E12*H12+$E14*H14+$E15*H15+$E16*H16+$E17*H17+$E18*H18+$E19*H19+$E13*H13 -> 7000 | I21: =$E6*I6+$E7*I7+$E8*I8+$E9*I9+$E10*I10+$E11*I11+$E12*I12+$E14*I14+$E15*I15+$E16*I16+$E17*I17+$E18*I18+$E19*I19+$E13*I13 -> 5000 | J21: =$E6*J6+$E7*J7+$E8*J8+$E9*J9+$E10*J10+$E11*J11+$E12*J12+$E14*J14+$E15*J15+$E16*J16+$E17*J17+$E18*J18+$E19*J19+$E13*J13 -> 6000 | K21: =$E6*K6+$E7*K7+$E8*K8+$E9*K9+$E10*K10+$E11*K11+$E12*K12+$E14*K14+$E15*K15+$E16*K16+$E17*K17+$E18*K18+$E19*K19+$E13*K13 -> 5500 | L21: =$E6*L6+$E7*L7+$E8*L8+$E9*L9+$E10*L10+$E11*L11+$E12*L12+$E14*L14+$E15*L15+$E16*L16+$E17*L17+$E18*L18+$E19*L19+$E13*L13 -> 6000 | M21: =$E6*M6+$E7*M7+$E8*M8+$E9*M9+$E10*M10+$E11*M11+$E12*M12+$E14*M14+$E15*M15+$E16*M16+$E17*M17+$E18*M18+$E19*M19+$E13*M13 -> 11000 | N21: =$E6*N6+$E7*N7+$E8*N8+$E9*N9+$E10*N10+$E11*N11+$E12*N12+$E14*N14+$E15*N15+$E16*N16+$E17*N17+$E18*N18+$E19*N19+$E13*N13 -> 9500 | O21: =$E6*O6+$E7*O7+$E8*O8+$E9*O9+$E10*O10+$E11*O11+$E12*O12+$E14*O14+$E15*O15+$E16*O16+$E17*O17+$E18*O18+$E19*O19+$E13*O13 -> 11000 | ... AU21: =$E6*AU6+$E7*AU7+$E8*AU8+$E9*AU9+$E10*AU10+$E11*AU11+$E12*AU12+$E14*AU14+$E15*AU15+$E16*AU16+$E17*AU17+$E18*AU18+$E19*AU19+$E13*AU13 -> 0

Sheet 9
B2: ■ DAILY MINIBAR SALES
B4: ITEM | C4: EXPIRATION DATE 1 | D4: EXPIRATION DATE 2 | E4: SALES PRICE | F4: TOTAL AMOUNT | G4: No. | H4: 1 | I4: 2 | J4: 3 | K4: 4 | L4: 5 | M4: 6 | N4: 7 | O4: 8 | P4: 9 | Q4: 10 | R4: 11 | S4: 12 | T4: 13 | U4: 14 | V4: 15 | W4: 16 | X4: 17 | Y4: 18 | Z4: 19 | AA4: 20 | AB4: 21 | AC4: 22 | AD4: 23 | AE4: 24 | AF4: 25 | AG4: 26 | AH4: 27 | AI4: 28 | AJ4: 29 | AK4: 30 | AL4: 31 | AM4: 32 | AN4: 33 | AO4: 34 | AP4: 35 | AQ4: 36 | AR4: 37 | AS4: 38 | AT4: 39 | AU4: 40
G5: Room No. | H5: 1015 | I5: 1229 | J5: 1627 | K5: 1606 | L5: 728 | M5: 1124 | N5: 729 | O5: 824 | P5: 1614 | Q5: 1022 | R5: 614 | S5: 531 | T5: 1022 | U5: 1731 | V5: 516 | W5: 1428 | X5: 1102 | Y5: 1714
B6: Potato Chip 감자칩 | C6: 2026년11월 | E6: 6000 | F6: =E6*G6 -> 36000 | G6: =SUM(H6:AU6) -> 6 | J6: 1 | K6: 1 | R6: 1 | S6: 1 | T6: 1 | Y6: 1
B7: Haribo Jelly 하리보 | C7: 2026년11월 | E7: 6500 | F7: =E7*G7 -> 26000 | G7: =SUM(H7:AU7) -> 4 | I7: 1 | R7: 1 | S7: 1 | W7: 1
B8: Fried Squid 오징어 | C8: 2026년7월 | E8: 7000 | F8: =E8*G8 -> 14000 | G8: =SUM(H8:AU8) -> 2 | J8: 1 | R8: 1
B9: Evian 에비앙 | C9: 2027년08월 | E9: 5500 | F9: =E9*G9 -> 60500 | G9: =SUM(H9:AU9) -> 11 | H9: 2 | I9: 1 | L9: 2 | N9: 1 | O9: 1 | P9: 1 | Q9: 1 | X9: 2
B10: Coke 콜라 | C10: 2027년12월 | E10: 4000 | F10: =E10*G10 -> 4000 | G10: =SUM(H10:AU10) -> 1 | M10: 1
B11: Zero Coke 제로 콜라 | C11: 2027년2월 | E11: 4000 | F11: =E11*G11 -> 4000 | G11: =SUM(H11:AU11) -> 1 | U11: 1
B12: Sprite 스프라이트 | C12: 2028년1월 | E12: 4000 | F12: =E12*G12 -> 8000 | G12: =SUM(H12:AU12) -> 2 | I12: 1 | U12: 1
B13: Red Bull 레드불 | C13: 2027년2월 | E13: 5000 | F13: =E13*G13 -> 0 | G13: =SUM(H13:AU13) -> 0
B14: Budweiser 버드와이저 | C14: 2026년11월 | E14: 7000 | F14: =E14*G14 -> 7000 | G14: =SUM(H14:AU14) -> 1 | V14: 1
B15: Cass 카스 | C15: 2027년3월 | E15: 7000 | F15: =E15*G15 -> 0 | G15: =SUM(H15:AU15) -> 0
B16: Despina 데스피나 | E16: 7000 | F16: =E16*G16 -> 0 | G16: =SUM(H16:AU16) -> 0
B17: Neptune Pale Ale 넵튠 에일 | E17: 7000 | F17: =E17*G17 -> 0 | G17: =SUM(H17:AU17) -> 0
B18: Two Face Black IPA 투페이스 | E18: 7000 | F18: =E18*G18 -> 0 | G18: =SUM(H18:AU18) -> 0
